Workbook
Name aquimsj1: 'Soja SS'!$E$30
Name aquimsj1: Camelina!$E$30
Name labsj1: NA()
Name semsj1: 'Soja SS'!$E$36
Name semsj1: Camelina!$E$37

Sheet Cotizaciones
A1: PROYECCIÓN ALEA SIEMBRA: COTIZACIONES
A4: MONEDAS | D4: LABORES (U$/Ha) // FLETES (U$/TON) | H4: AGROQUÍMICOS/FERTILIZANTES (U$/Unid) | L4: PRODUCTO (U$/Ton)
A5: Dólar | B5: 10 | D5: Análisis | E5: 13 | H5: 2,4-D | I5: 4.6 | J5: Lt | L5: 43132 | M5: 19.97
A6: Euro | B6: 6 | D6: Aplicación Cebo | E6: - | F6: 5 | H6: Aceite Vegetal | I6: 3 | J6: Lt | L6: 43160 | M6: 20.285
D7: Cultivador | E7: 170 | H7: Acetoclor | I7: 7.2 | J7: Lt | L7: 43191 | M7: 20.679
A8: PRODUCTO (U$/Ton) | C8: Px bruto | D8: Disco, Rastra y Rolo | E8: 600 | H8: Allegro | I8: 20 | J8: Lt | L8: 43221 | M8: 20.97
A9: Cebada Cervera | B9: 245 | D9: Escardillo | E9: 180 | H9: Arrancador Azufrado | I9: 770 | J9: Ton | L9: 43252 | M9: 21.28
A10: Cebada Forrajera | B10: 220 | D10: Fertilización Urea | E10: =180*1.15 -> 207 | H10: Atrazina granulada | I10: 5.7 | J10: kg | L10: 43282 | M10: 21.61
A11: Colza | D11: Fertilización UAN | E11: =80*1.15 -> 92 | H11: Axial | I11: 39 | J11: Lt | L11: 43313 | M11: 21.92 | N11: rofex
A12: Girasol | B12: 450 | D12: Limpieza, Curada e Inoculada | E12: =420*1.15 -> 483 | H12: Bellis | I12: 39 | J12: Lt | L12: 43344 | M12: 22.2
A13: Maíz | B13: 200 | D13: Medición Satelital | E13: - | H13: Caramba | I13: 16.7 | J13: Lt | L13: 43374 | M13: 22.52
A14: Soja | B14: 355 | D14: Monitoreo B y BB. | E14: - | F14: 5 | H14: Cebo | I14: 7 | J14: Lt | L14: 43405 | M14: 22.81
A15: Trigo | B15: 230 | C15: =+'Trigo SP'!E73 -> 201.04308 | D15: Muestreo de Suelos | E15: - | F15: 1 | H15: lambda 25% | I15: 20 | J15: Lt | L15: 43435 | M15: 22.95
D16: Pulverización Aerea | F16: 13 | H16: Clearsol | I16: 170 | J16: 12 | L16: 43466 | M16: 23.25
D17: Pulverización Terrestre | F17: 5 | H17: Clearsol Plus | I17: 20 | L17: 43497 | M17: 23.553922
D18: Rolo Picador | F18: 17 | H18: Clorimuron | I18: =21*1.05 -> 22.05 | J18: Kg | L18: 43525 | M18: 23.861816
D19: Siembra Conv. Fina | H19: Clorpirifos | I19: 7 | J19: Lt | L19: 43556 | M19: 24.173735
D20: Siembra Conv. Gruesa | H20: Coadyudante (Acampo max N)18 | I20: 20 | J20: Lt | L20: 43586 | M20: 24.489732
D21: Siembra Directa Fina | F21: 42 | H21: Coadyugante Extremo | I21: 12 | J21: Lt
D22: Siembra Directa Gruesa | F22: 42 | H22: Curasemillas Fina (sist) | I22: 80 | J22: tn
H23: Dicamba | I23: 7 | J23: Lt
D24: Extracción Embolsado | F24: 3.3 | H24: Fluorucloridona | I24: 11.8 | J24: Lt
D25: Flete Cereal 110 kms | F25: 20 | H25: Fosforo (MAP / DAP) | I25: 990 | J25: Ton | K25: Aproximado
D26: Flete Semilla 110 kms | F26: 35 | H26: Orquesta | I26: 28 | J26: Lt
D27: Secada Cebada Cervecera | F27: 3 | H27: Cletodyn | I27: 6 | J27: Lt
D28: Secada Cebada Forrajera | F28: 3 | H28: Glifosato | I28: 4.5 | J28: Lt | K28: 0.54
D29: Secada Colza | F29: 3 | H29: Inoculante (Combi full action) | I29: 250 | J29: pack (3 ton)
D30: Secada Maíz | F30: 3 | H30: coragen | I30: 100 | J30: Lt
D31: Secada Girasol | F31: 3 | H31: lambda 25% | I31: 20 | J31: Lt
H32: MCPA 75 % | I32: 11
D33: Secada Soja | F33: 3 | H33: Lontrel | I33: 35 | J33: Lt
D34: Secada Trigo | F34: 3 | H34: Nitrogeno (Urea) | I34: 610 | J34: Ton | K34: Aproximado
D35: Paritaria | F35: 5 | H35: Nitrogeno Líquido 32% (Solmix) | I35: 440 | J35: Ton
D36: Traspile | F36: 6.5 | H36: Picloran | I36: 7 | J36: l
H37: Metsulfuron | I37: 35 | J37: Kg
H38: Peack Pack | I38: 125 | J38: Pack
D39: SEMILLA (U$/Ton) | H39: Pibot | I39: 8 | J39: Lt
D40: Semilla Cebada Curada | E40: 0.52 | F40: Ton | H40: Silobolsa Fina | I40: 380 | J40: 220 tn
D41: Semilla Colza | E41: 300 | F41: bolsa 20 Kg | H41: Silobolsa Gruesa | I41: 410 | J41: 210 tons
D42: Semilla Girasol | E42: 300 | F42: 150mil Sem | H42: Sulfato de Amonio | I42: 1.1 | J42: lts
...

Sheet Resumen Proy
A1: Proyeccion General 2526
Q3: SUELOS PROFUNDOS | AC3: doble cultivo
B4: Has | C4: Rinde | D4: Arrend. | E4: Precio | F4: Ingreso Bruto | G4: Costo | H4: Px dolor | I4: R. Indif | J4: Resultado | K4: Inversión Real | L4: costo prod/tn | M4: costo tn/Px | N4: Retorno | O4: Retorno | Q4: Administración | AC4: Retorno | AD4: Retorno
C5: Tons / Ha | D5: U$ / Ha | E5: U$ / Ton | F5: U$ / Ha | G5: U$ / Ha | I5: Tons / Ha | J5: U$ / Ha | K5: U$ / Ha | N5: Inversion | O5: costos | Q5: u$ / Ton | R5: U$ | S5: $ | AC5: costos | AD5: Inversion
A6: Trigo / SOJA 2DA | B6: ='Trigo SP'!B3 -> 0 | C6: ='Trigo SP'!B75 -> 5.7 | D6: =+C57 -> 426 | E6: =Cotizaciones!B15 -> 230 | F6: =+'Trigo SP'!B79 -> 1123.0267 | G6: ='Trigo SP'!B77 -> 1026.77 | H6: =+('Trigo SP'!B77+'Trigo SP'!E70)/'Trigo SP'!B75 -> 209.09201 | I6: ='Trigo SP'!B82 -> 5.1072138 | J6: ='Trigo SP'!B80 -> 96.256658 | K6: ='Trigo SP'!B83 -> 921.77 | L6: =+G6/C6 -> 180.13509 | M6: =+L6/E6 -> 0.78319603 | N6: =+'Trigo SP'!B84 -> 0.1044259 | O6: =+'Trigo SP'!B81 -> 0.09374705 | P6: =G6*B6 -> 0 | Q6: ='[1]Trigo SP'!E30 -> 50.35 | R6: =Q6*B6 -> 0 | S6: =R6*[1]Cotizaciones!$B$5 -> 0 | T6: Trigo / Soja 2da | AA6: =(J6+G6)*B6 -> 0 | AC6: =+'Trigo SP'!H81 -> Ha | AD6: =+'Trigo SP'!H84 -> 0
B7: =+'Soja 2da. T'!B3 -> 0 | C7: ='Soja 2da. T'!B73 -> 1.3 | D7: 0 | E7: =+Cotizaciones!B14 -> 355 | F7: =+'Soja 2da. T'!B76 -> 414.33491 | G7: =+'Soja 2da. T'!B75 -> 404.65 | H7: =+('Soja 2da. T'!B75+'Soja 2da. T'!E67)/'Soja 2da. T'!B73 -> 347.55007 | I7: =+'Soja 2da. T'!B79 -> 1.269613 | J7: =+'Soja 2da. T'!B77 -> 9.6849149 | K7: =+'Soja 2da. T'!B80 -> 296.65 | L7: =+G7/C7 -> 311.26923 | M7: =+L7/E7 -> 0.87681473 | N7: =+'Soja 2da. T'!B81 -> 0.032647615 | O7: =+'Soja 2da. T'!B78 -> 0.023934054 | P7: =G7*B7 -> 0 | Q7: ='[1]Soja 2da. C'!E28 -> 22.4 | R7: =Q7*B7 -> 0 | S7: =R7*[1]Cotizaciones!$B$5 -> 0 | AA7: =(J7+G7)*B7 -> 0
A8: Cebada / Soja 2da | B8: =+'Cebada SP'!B3 -> 0 | C8: ='Cebada SP'!B80 -> 5.7 | D8: =+'Cebada SP'!D26 -> 426 | E8: =+Cotizaciones!B9 -> 245 | F8: ='Cebada SP'!B84 -> 1152.7368 | G8: ='Cebada SP'!B82 -> 1044.71 | H8: =+('Cebada SP'!B82+'Cebada SP'!E73)/'Cebada SP'!B80 -> 209.67069 | I8: ='Cebada SP'!B87 -> 5.0625172 | J8: =+'Cebada SP'!B85 -> 108.02684 | K8: ='Cebada SP'!B88 -> 939.71 | L8: =+G8/C8 -> 183.28246 | M8: =+L8/E8 -> 0.74809166 | N8: =+'Cebada SP'!B89 -> 0.11495764 | O8: =+'Cebada SP'!B86 -> 0.10340367 | P8: =G8*B8 -> 0 | Q8: ='[1]Cebada SP'!E30 -> 52.5 | R8: =Q8*B8 -> 0 | S8: =R8*[1]Cotizaciones!$B$5 -> 0 | T8: Cebada / Soja 2da | AA8: =(J8+G8)*B8 -> 0 | AC8: =+'Soja 2da. C'!D79 -> 0.12567587 | AD8: =+'Cebada SP'!E87 -> 0.14623846 | AF8: =+B8*C8 -> 0
B9: =+'Soja 2da. C'!B3 -> 0 | C9: ='Soja 2da. C'!B74 -> 1.5 | D9: 0 | E9: =Cotizaciones!B14 -> 355 | F9: ='Soja 2da. C'!B77 -> 472.41267 | G9: ='Soja 2da. C'!B76 -> 399 | H9: =+('Soja 2da. C'!B76+'Soja 2da. C'!E68)/'Soja 2da. C'!B74 -> 299.63083 | I9: ='Soja 2da. C'!B80 -> 1.2415628 | J9: =+'Soja 2da. C'!B78 -> 73.412673 | K9: ='Soja 2da. C'!B81 -> 301 | L9: =+G9/C9 -> 266 | M9: =+L9/E9 -> 0.74929577 | N9: =+'Soja 2da. C'!B82 -> 0.24389592 | O9: =+'Soja 2da. C'!B79 -> 0.18399166 | P9: =G9*B9 -> 0 | Q9: ='[1]Soja 2da. C'!E28 -> 22.4 | R9: =Q9*B9 -> 0 | S9: =R9*[1]Cotizaciones!$B$5 -> 0 | AA9: =(J9+G9)*B9 -> 0 | AF9: =+B9*C9 -> 0
A10: Maiz 2da | B10: 0 | C10: =+'Maiz 2da'!B76 -> 4.5 | D10: 0 | E10: =+Cotizaciones!B13 -> 200 | F10: =+'Maiz 2da'!B79 -> 719.72853 | G10: =+'Maiz 2da'!E69 -> 654.65 | I10: =+'Maiz 2da'!B82 -> 4.0112437 | J10: =+F10-G10 -> 65.078528 | K10: =+'Maiz 2da'!B83 -> 536.61 | L10: =+G10/C10 -> 145.47778 | M10: =+L10/E10 -> 0.72738889 | N10: =+'Maiz 2da'!B84 -> 0.12127714 | O10: =+'Maiz 2da'!B81 -> 0.099409651 | P10: =G10*B10 -> 0 | R10: =Q10*B10 -> 0 | S10: =R10*[1]Cotizaciones!$B$5 -> 0 | T10: Colza / Soja 2da | AA10: =(J10+G10)*B10 -> 0 | AC10: =+'Maiz 2da'!D81 -> 0.10186504
A11: Girasol | B11: =+'Girasol SP'!B3 -> 0 | C11: =+'Girasol SP'!B83 -> 2.6 | D11: =+'Girasol SP'!E28 -> 426 | E11: =+Cotizaciones!B12 -> 450 | F11: ='Girasol SP'!B89 -> 971.77383 | G11: ='Girasol SP'!B88 -> 972.71 | H11: =+('Girasol SP'!B88+'Girasol SP'!E77)/'Girasol SP'!B83-'Girasol SP'!B85 -> 358.36007 | I11: =+'Girasol SP'!B92 -> 2.6025047 | J11: =+F11-G11 -> -0.93617029 | K11: =+'Girasol SP'!B93 -> 872.71 | L11: =+G11/C11 -> 374.11923 | M11: =+L11/E11 -> 0.83137607 | N11: =+'Girasol SP'!B94 -> -0.0010727164 | O11: =+'Girasol SP'!B91 -> -0.00096243514 | P11: =G11*B11 -> 0 | Q11: ='[1]Soja 2da. C'!E28 -> 22.4 | R11: =Q11*B11 -> 0 | S11: =R11*[1]Cotizaciones!$B$5 -> 0 | AA11: =(J11+G11)*B11 -> 0 | AC11: =+'Girasol 2da'!D75 -> 0 | AF11: =+B11*C11 -> 0
A12: Maíz | B12: ='Maiz SP'!B3 -> 0 | C12: ='Maiz SP'!B76 -> 8.5 | D12: =+'Maiz SP'!D27 -> 426 | E12: =Cotizaciones!B13 -> 200 | F12: ='Maiz SP'!B79 -> 1346.5629 | G12: ='Maiz SP'!B78 -> 1152.01 | H12: =+('Maiz SP'!B78+'Maiz SP'!E71)/'Maiz SP'!B76 -> 177.11142 | I12: ='Maiz SP'!B82 -> 7.2719106 | J12: =+'Maiz SP'!B80 -> 194.5529 | K12: ='Maiz SP'!B83 -> 1017.01 | L12: =+G12/C12 -> 135.53059 | M12: =+L12/E12 -> 0.67765294 | N12: ='Maiz SP'!B84 -> 0.19129891 | O12: ='Maiz SP'!B81 -> 0.16888126 | P12: =G12*B12 -> 0 | R12: =Q12*B12 -> 0 | S12: =R12*[1]Cotizaciones!$B$5 -> 0 | T12: Maíz | AA12: =(J12+G12)*B12 -> 0 | AF12: =+B12*C12 -> 0
A13: Girasol Oleico | B13: ='Girasol O SP'!B3 -> 0 | C13: ='Girasol O SP'!B80 -> 2.6 | D13: =+'Girasol O SP'!D27 -> 426 | E13: ='Girasol O SP'!B85 -> 380.21917 | F13: ='Girasol O SP'!B87 -> 968.79843 | G13: ='Girasol O SP'!B86 -> 975.72667 | H13: =+('Girasol O SP'!B86+'Girasol O SP'!E73)/'Girasol O SP'!B80-'Girasol O SP'!B82 -> 355.06032 | I13: ='Girasol O SP'!B90 -> 2.5662217 | J13: =+'Girasol O SP'!B88 -> -6.9282335 | K13: ='Girasol O SP'!B91 -> 875.72667 | L13: =+G13/C13 -> 375.27949 | M13: =+L13/E13 -> 0.98700834 | N13: ='Girasol O SP'!B92 -> -0.007911411 | O13: ='Girasol O SP'!B89 -> -0.0071005885 | P13: =G13*B13 -> 0 | R13: =Q13*B13 -> 0 | AA13: =(J13+G13)*B13 -> 0
A14: Girasol | B14: 0 | C14: ='Girasol SP'!B83 -> 2.6 | D14: =+'Girasol SP'!D28 -> 426 | E14: ='Girasol SP'!B87 -> 373.75917 | F14: ='Girasol SP'!B89 -> 971.77383 | G14: ='Girasol SP'!B88 -> 972.71 | I14: ='Girasol SP'!B92 -> 2.6025047 | J14: =+'Girasol SP'!B90 -> -0.93617029 | K14: ='Girasol SP'!B93 -> 872.71 | L14: =+G14/C14 -> 374.11923 | M14: =+L14/E14 -> 1.0009634 | N14: ='Girasol SP'!B94 -> -0.0010727164 | O14: ='Girasol SP'!B91 -> -0.00096243514 | P14: =G14*B14 -> 0 | R14: =Q14*B14 -> 0 | S14: =R14*[1]Cotizaciones!$B$5 -> 0 | T14: Girasol | AA14: =(J14+G14)*B14 -> 0
A15: Soja | B15: =Camelina!B3 -> 0 | C15: =Camelina!B82 -> 1 | D15: =+C57 -> 426 | E15: =Cotizaciones!B14 -> 355 | F15: =Camelina!B85 -> 416.45 | G15: =Camelina!B84 -> 399.5 | I15: =Camelina!B88 -> 0.95929884 | J15: =+Camelina!B86 -> 16.95 | K15: =Camelina!B89 -> 304.5 | L15: =+G15/C15 -> 399.5 | M15: =+L15/E15 -> 1.1253521 | N15: =Camelina!B90 -> 0.055665025 | O15: =Camelina!B87 -> 0.042428035 | P15: =G15*B15 -> 0 | R15: =Q15*B15 -> 0 | S15: =R15*[1]Cotizaciones!$B$5 -> 0 | T15: Soja | AA15: =(J15+G15)*B15 -> 0
A16: TOTAL / HA | B16: =+B12+B8+B14+B6+B15+B13 -> 0 | C16: =((C6*B6)+(C7*B7)+(C8*B8)+(C9*B9)+(C10*B10)+(C11*B11)+(C12*B12)+(C13*B13)+(C14*B14)+(C15*B15))/(B16+B11+B9+B7) -> #DIV/0! | D16: =((D6*B6)+(D7*B7)+(D8*B8)+(D9*B9)+(D10*B10)+(D11*B11)+(D12*B12)+(D13*B13)+(D14*B14)+(D15*B15))/B16 -> #DIV/0! | E16: =((E6*B6)+(E7*B7)+(E8*B8)+(E9*B9)+(E10*B10)+(E11*B11)+(E12*B12)+(E13*B13)+(E14*B14)+(E15*B15))/(B16+B7+B9+B11) -> #DIV/0! | F16: =((F6*B6)+(F7*B7)+(F8*B8)+(F9*B9)+(F10*B10)+(F11*B11)+(F12*B12)+(F13*B13)+(F14*B14)+(F15*B15))/(B16) -> #DIV/0! | G16: =((G6*B6)+(G7*B7)+(G8*B8)+(G9*B9)+(G10*B10)+(G11*B11)+(G12*B12)+(G13*B13)+(G14*B14)+(G15*B15))/(B16) -> #DIV/0! | I16: =((I6*B6)+(I7*B7)+(I8*B8)+(I9*B9)+(I10*B10)+(I11*B11)+(I12*B12)+(I13*B13)+(I14*B14)+(I15*B15))/(B16+B7+B9+B11) -> #DIV/0! | J16: =J17/B16 -> #DIV/0! | K16: =((K6*B6)+(K7*B7)+(K8*B8)+(K9*B9)+(K10*B10)+(K11*B11)+(K12*B12)+(K13*B13)+(K14*B14)+(K15*B15))/(B16+B7+B9+B11) -> #DIV/0! | N16: RI | O16: =J16/K16 -> #DIV/0! | P16: =SUM(P6:P15) -> 0 | Q16: =SUM(Q6:Q15) -> 170.05 | R16: =SUM(R6:R15) -> 0 | S16: =SUM(S6:S15) -> 0 | T16: =SUM(T6:T15) -> 0 | U16: =SUM(U6:U15) -> 0 | V16: =SUM(V6:V15) -> 0 | W16: =SUM(W6:W15) -> 0 | ... AA16: =SUM(AA6:AA15) -> 0
A17: TOTAL | D17: =+'[2]Alquileres por campo'!$S$64 -> 0 | F17: =((F6*B6)+(F7*B7)+(F8*B8)+(F9*B9)+(F10*B10)+(F11*B11)+(F12*B12)+(F13*B13)+(F14*B14)+(F15*B15)) -> 0 | G17: =((G6*B6)+(G7*B7)+(G8*B8)+(G9*B9)+(G10*B10)+(G11*B11)+(G12*B12)+(G13*B13)+(G14*B14)+(G15*B15)) -> 0 | J17: =((J6*B6)+(J7*B7)+(J8*B8)+(J9*B9)+(J10*B10)+(J11*B11)+(J12*B12)+(J13*B13)+(J14*B14)+(J15*B15)) -> 0 | K17: =((K6*B6)+(K7*B7)+(K8*B8)+(K9*B9)+(K10*B10)+(K11*B11)+(K12*B12)+(K13*B13)+(K14*B14)+(K15*B15)) -> 0 | N17: RC | O17: =J16/G16 -> #DIV/0!
B19: SUELOS SOMEROS
B20: Has | C20: Rinde | D20: Arrend. | E20: Precio | F20: Ingreso Bruto | G20: Costo | I20: Rinde Indif | J20: Resultado | K20: Inversión Real | N20: Retorno | O20: Retorno
C21: Tons / Ha | D21: U$ / Ha | E21: U$ / Ton | F21: U$ / Ha | G21: U$ / Ha | I21: Tons / Ha | J21: u$ / Ton | K21: U$ / ha | N21: Real | O21: Nominal
A22: Trigo / Soja 2da | B22: 0 | C22: ='Trigo SS'!B71 -> 4 | D22: 224 | E22: =E6 -> 230 | F22: ='Trigo SS'!B74 -> 920 | G22: ='Trigo SS'!B73 -> 722.52875 | I22: ='Trigo SS'!B77 -> 3.0386015 | J22: ='Trigo SS'!B75 -> 197.47125 | K22: ='Trigo SS'!B78 -> 497.25 | N22: ='Trigo SS'!B79 -> 0.3971267 | O22: ='Trigo SS'!H79 -> 0.26093483 | P22: =G22*B22 -> 0 | Q22: ='[1]Trigo SP'!E46 -> 78.845 | R22: =Q22*B22 -> 0 | S22: =R22*[1]Cotizaciones!$B$5 -> 0 | T22: Trigo / Soja 2da | AA22: =(J22+G22)*B22 -> 0
B23: 0 | C23: =C7 -> 1.3 | D23: 56 | E23: =E7 -> 355 | F23: ='Soja 2da. T'!B76 -> 414.33491 | G23: =G7 -> 404.65 | I23: =I7 -> 1.269613 | J23: =J7 -> 9.6849149 | K23: =K7 -> 296.65 | N23: =N7 -> 0.032647615 | P23: =G23*B23 -> 0 | Q23: ='[1]Soja 2da. C'!E44 -> 5.118 | R23: =Q23*B23 -> 0 | S23: =R23*[1]Cotizaciones!$B$5 -> 0 | AA23: =(J23+G23)*B23 -> 0
A24: Cebada / Soja 2da | B24: 0 | C24: ='Cebada SS '!B73 -> 5 | D24: 224 | E24: =E8 -> 245 | F24: ='Cebada SS '!B76 -> 1225 | G24: =+'Cebada SS '!E70 -> 832.447 | I24: ='Cebada SS '!B79 -> 3.2189065 | J24: ='Cebada SS '!B77 -> 392.553 | K24: ='Cebada SS '!B80 -> 569.865 | N24: ='Cebada SS '!B81 -> 0.68885262 | O24: ='Cebada SS '!B78 -> 0.47156516 | P24: =G24*B24 -> 0 | Q24: ='[1]Cebada SP'!E46 -> 0 | R24: =Q24*B24 -> 0 | S24: =R24*[1]Cotizaciones!$B$5 -> 0 | T24: Cebada / Soja 2da | AA24: =(J24+G24)*B24 -> 0
B25: 0 | C25: ='Soja 2da. C'!B74 -> 1.5 | D25: 56 | E25: =E9 -> 355 | F25: ='Soja 2da. C'!B77 -> 472.41267 | G25: ='Soja 2da. C'!B76 -> 399 | I25: ='Soja 2da. C'!B80 -> 1.2415628 | J25: ='Soja 2da. C'!B78 -> 73.412673 | K25: ='Soja 2da. C'!B81 -> 301 | P25: =G25*B25 -> 0 | Q25: ='[1]Soja 2da. C'!E44 -> 5.118 | R25: =Q25*B25 -> 0 | S25: =R25*[1]Cotizaciones!$B$5 -> 0 | AA25: =(J25+G25)*B25 -> 0
A26: Colza / Soja 2da | B26: 0 | C26: ='Girasol 2da'!B69 -> 1.3 | D26: 224 | E26: =E10 -> 200 | F26: ='Girasol 2da'!B73 -> 522.91365 | G26: ='Girasol 2da'!B72 -> 507.33333 | I26: ='Girasol 2da'!B76 -> 1.1236735 | J26: ='Girasol 2da'!B74 -> 15.580321 | K26: ='Girasol 2da'!B77 -> 411.29333 | N26: ='Girasol 2da'!B78 -> 0.037881288 | O26: ='Girasol 2da'!H78 -> 0 | P26: =G26*B26 -> 0 | R26: =Q26*B26 -> 0 | S26: =R26*[1]Cotizaciones!$B$5 -> 0 | T26: Colza / Soja 2da | AA26: =(J26+G26)*B26 -> 0
B27: 0 | C27: ='Soja 2da. Co'!B71 -> 1.5 | D27: 56 | E27: =E11 -> 450 | F27: ='Soja 2da. Co'!B74 -> 532.5 | G27: =G11 -> 972.71 | I27: =I11 -> 2.6025047 | J27: =J11 -> -0.93617029 | K27: =K11 -> 872.71 | N27: =N11 -> -0.0010727164 | P27: =G27*B27 -> 0 | Q27: ='[1]Soja 2da. C'!E44 -> 5.118 | R27: =Q27*B27 -> 0 | S27: =R27*[1]Cotizaciones!$B$5 -> 0 | AA27: =(J27+G27)*B27 -> 0
A28: Maíz | B28: 0 | C28: 5.5 | D28: 0 | E28: 0 | F28: 0 | G28: 0 | I28: 0 | J28: 0 | K28: 0 | N28: 0 | P28: =G28*B28 -> 0 | R28: =Q28*B28 -> 0 | S28: =R28*[1]Cotizaciones!$B$5 -> 0 | T28: Maíz | AA28: =(J28+G28)*B28 -> 0
A29: Girasol | B29: 0 | C29: 2 | D29: 280 | E29: =E14 -> 373.75917 | F29: ='Girasol SS'!B82 -> 1166.4 | G29: ='Girasol SS'!B81 -> 745.87253 | I29: ='Girasol SS'!B85 -> 1.4863064 | J29: ='Girasol SS'!B83 -> 420.52747 | K29: ='Girasol SS'!B86 -> 550.93333 | N29: ='Girasol SS'!B87 -> 0.7633001 | P29: =G29*B29 -> 0 | R29: =Q29*B29 -> 0 | AA29: =(J29+G29)*B29 -> 0
A30: Girasol Oleico | B30: 0 | C30: ='Girasol O SS'!B74 -> 2 | D30: 280 | E30: =E13 -> 380.21917 | F30: =E30*C30 -> 760.43833 | G30: ='Girasol O SS'!B80 -> 740.01536 | I30: ='Girasol O SS'!B84 -> 1.3690907 | J30: ='Girasol O SS'!B82 -> 311.98464 | K30: ='Girasol O SS'!B85 -> 546.08 | N30: ='Girasol O SS'!B86 -> 0.57131673 | O30: ='Girasol O SS'!B83 -> 0.42159211 | P30: =G30*B30 -> 0 | R30: =Q30*B30 -> 0 | S30: =R30*[1]Cotizaciones!$B$5 -> 0 | T30: Girasol | AA30: =(J30+G30)*B30 -> 0
A31: Soja | B31: 0 | C31: ='Soja SS'!B81 -> 2.8 | D31: 280 | E31: =E15 -> 355 | F31: ='Soja SS'!B84 -> 994 | G31: ='Soja SS'!E73 -> 934.2697 | I31: ='Soja SS'!B87 -> 2.6185868 | J31: ='Soja SS'!B85 -> 59.7303 | K31: ='Soja SS'!B88 -> 653.15 | N31: ='Soja SS'!B89 -> 0.09144959 | O31: ='Soja SS'!B86 -> 0.069279053 | P31: =G31*B31 -> 0 | R31: =Q31*B31 -> 0 | S31: =R31*[1]Cotizaciones!$B$5 -> 0 | T31: Soja | AA31: =(J31+G31)*B31 -> 0
A32: TOTAL / HA | B32: =SUM(B22:B31)-B23-B25-B27 -> 0 | C32: =((C22*B22)+(C23*B23)+(C24*B24)+(C25*B25)+(C26*B26)+(C27*B27)+(C28*B28)+(C29*B29)+(C30*B30)+(C31*B31))/(B32+B27+B25+B23) -> #DIV/0! | D32: =((D22*B22)+(D23*B23)+(D24*B24)+(D25*B25)+(D26*B26)+(D27*B27)+(D28*B28)+(D29*B29)+(D30*B30)+(D31*B31))/B32 -> #DIV/0! | E32: =((E22*B22)+(E23*B23)+(E24*B24)+(E25*B25)+(E26*B26)+(E27*B27)+(E28*B28)+(E29*B29)+(E30*B30)+(E31*B31))/(B32+B23+B25+B27) -> #DIV/0! | F32: =((F22*B22)+(F23*B23)+(F24*B24)+(F25*B25)+(F26*B26)+(F27*B27)+(F28*B28)+(F29*B29)+(F30*B30)+(F31*B31))/(B32+B25) -> #DIV/0! | G32: =((G22*B22)+(G23*B23)+(G24*B24)+(G25*B25)+(G26*B26)+(G27*B27)+(G28*B28)+(G29*B29)+(G30*B30)+(G31*B31))/(B32+B25) -> #DIV/0! | I32: =((I22*B22)+(I23*B23)+(I24*B24)+(I25*B25)+(I26*B26)+(I27*B27)+(I28*B28)+(I29*B29)+(I30*B30)+(I31*B31))/(B32+B23+B25+B27) -> #DIV/0! | J32: =((J22*B22)+(J23*B23)+(J24*B24)+(J25*B25)+(J26*B26)+(J27*B27)+(J28*B28)+(J29*B29)+(J30*B30)+(J31*B31))/(B32+B25) -> #DIV/0! | K32: =((K22*B22)+(K23*B23)+(K24*B24)+(K25*B25)+(K26*B26)+(K27*B27)+(K28*B28)+(K29*B29)+(B30*K30)+(K31*B31))/(B32+B25) -> #DIV/0! | N32: RR | O32: =J32/K32 -> #DIV/0! | P32: =SUM(P22:P31) -> 0 | Q32: =SUM(Q22:Q31) -> 94.199 | R32: =SUM(R22:R31) -> 0 | S32: =SUM(S22:S31) -> 0 | T32: =SUM(T22:T31) -> 0 | U32: =SUM(U22:U31) -> 0 | V32: =SUM(V22:V31) -> 0 | W32: =SUM(W22:W31) -> 0 | ... AA32: =SUM(AA22:AA31) -> 0
A33: TOTAL | D33: =((D22*B22)+(D23*B23)+(D24*B24)+(D25*B25)+(D26*B26)+(D27*B27)+(D28*B28)+(D29*B29)+(D30*B30)+(D31*B31)) -> 0 | F33: =((F22*B22)+(F23*B23)+(F24*B24)+(F25*B25)+(F26*B26)+(F27*B27)+(F28*B28)+(F29*B29)+(F30*B30)+(F31*B31)) -> 0 | G33: =((G22*B22)+(G23*B23)+(G24*B24)+(G25*B25)+(G26*B26)+(G27*B27)+(G28*B28)+(G29*B29)+(G30*B30)+(G31*B31)) -> 0 | J33: =((J22*B22)+(J23*B23)+(J24*B24)+(J25*B25)+(J26*B26)+(J27*B27)+(J28*B28)+(J29*B29)+(J30*B30)+(J31*B31)) -> 0 | K33: =((K22*B22)+(K23*B23)+(K24*B24)+(K25*B25)+(K26*B26)+(K27*B27)+(K28*B28)+(K29*B29)+(B30*K30)+(K31*B31)) -> 0 | N33: RN | O33: =J32/G32 -> #DIV/0!
B35: PROYECTO GENERAL
B36: Has | C36: Rinde | D36: Arrend. | E36: Precio | F36: Ingreso Bruto | G36: Costo | I36: Rinde Indif | J36: Resultado | K36: Inversión Real | N36: Retorno | O36: Retorno
C37: Tons / Ha | D37: U$ / Ha | E37: U$ / Ton | F37: U$ / Ha | G37: U$ / Ha | I37: Tons / Ha | J37: u$ / Ton | K37: U$ / Ton | N37: Real | O37: Nominal
A38: Trigo / Soja 2da | B38: =B22+B6 -> 0 | C38: =((B6*C6)+(B22*C22))/B38 -> #DIV/0! | D38: =((D6*B6)+(D22*B22))/B38 -> #DIV/0! | E38: =E6 -> 230 | F38: =((F6*B6)+(F22*B22))/B38 -> #DIV/0! | G38: =((G6*B6)+(G22*B22))/B38 -> #DIV/0! | I38: =((I6*B6)+(I22*B22))/B38 -> #DIV/0! | J38: =((J6*B6)+(J22*B22))/B38 -> #DIV/0! | K38: =((K6*B6)+(K22*B22))/B38 -> #DIV/0! | N38: =(J38+J39)/(K38+K39) -> #DIV/0! | O38: =(J38+J39)/(G38+G39) -> #DIV/0! | P38: =G38*B38 -> #DIV/0! | Q38: ='[1]Trigo SP'!E62 -> 11.034707 | R38: =Q38*B38 -> 0 | S38: =R38*[1]Cotizaciones!$B$5 -> 0 | T38: Trigo / Soja 2da | AA38: =(J38+G38)*B38 -> #DIV/0!
B39: =B23+B7 -> 0 | C39: =((B7*C7)+(B23*C23))/B39 -> #DIV/0! | D39: =((D7*B7)+(D23*B23))/B39 -> #DIV/0! | E39: =E7 -> 355 | F39: =((F7*B7)+(F23*B23))/B39 -> #DIV/0! | G39: =((G7*B7)+(G23*B23))/B39 -> #DIV/0! | I39: =((I7*B7)+(I23*B23))/B39 -> #DIV/0! | J39: =((J7*B7)+(J23*B23))/B39 -> #DIV/0! | K39: =((K7*B7)+(K23*B23))/B39 -> #DIV/0! | P39: =G39*B39 -> #DIV/0! | Q39: ='[1]Soja 2da. C'!E60 -> #REF! | R39: =Q39*B39 -> #REF! | S39: =R39*[1]Cotizaciones!$B$5 -> #REF! | AA39: =(J39+G39)*B39 -> #DIV/0!
A40: Cebada / Soja 2da | B40: =B24+B8 -> 0 | C40: =((B8*C8)+(B24*C24))/B40 -> #DIV/0! | D40: =((D8*B8)+(D24*B24))/B40 -> #DIV/0! | E40: =E8 -> 245 | F40: =((F8*B8)+(F24*B24))/B40 -> #DIV/0! | G40: =((G8*B8)+(G24*B24))/B40 -> #DIV/0! | I40: =((I8*B8)+(I24*B24))/B40 -> #DIV/0! | J40: =((J8*B8)+(J24*B24))/B40 -> #DIV/0! | K40: =((K8*B8)+(K24*B24))/B40 -> #DIV/0! | N40: =(J40+J41)/(K40+K41) -> #DIV/0! | O40: =(J40+J41)/(G40+G41) -> #DIV/0! | P40: =G40*B40 -> #DIV/0! | Q40: ='[1]Cebada SP'!E62 -> 131.13585 | R40: =Q40*B40 -> 0 | S40: =R40*[1]Cotizaciones!$B$5 -> 0 | T40: Cebada / Soja 2da | AA40: =(J40+G40)*B40 -> #DIV/0!
B41: =B25+B9 -> 0 | C41: =((B9*C9)+(B25*C25))/B41 -> #DIV/0! | D41: =((D9*B9)+(D25*B25))/B41 -> #DIV/0! | E41: =E9 -> 355 | F41: =((F9*B9)+(F25*B25))/B41 -> #DIV/0! | G41: =((G9*B9)+(G25*B25))/B41 -> #DIV/0! | I41: =((I9*B9)+(I25*B25))/B41 -> #DIV/0! | J41: =((J9*B9)+(J25*B25))/B41 -> #DIV/0! | K41: =((K9*B9)+(K25*B25))/B41 -> #DIV/0! | P41: =G41*B41 -> #DIV/0! | Q41: ='[1]Soja 2da. C'!E60 -> #REF! | R41: =Q41*B41 -> #REF! | S41: =R41*[1]Cotizaciones!$B$5 -> #REF! | AA41: =(J41+G41)*B41 -> #DIV/0!
A42: Colza / Soja 2da | B42: =B26+B10 -> 0 | C42: =((B10*C10)+(B26*C26))/B42 -> #DIV/0! | D42: =((D10*B10)+(D26*B26))/B42 -> #DIV/0! | E42: =E10 -> 200 | F42: =((F10*B10)+(F26*B26))/B42 -> #DIV/0! | G42: =((G10*B10)+(G26*B26))/B42 -> #DIV/0! | I42: =((I10*B10)+(I26*B26))/B42 -> #DIV/0! | J42: =((J10*B10)+(J26*B26))/B42 -> #DIV/0! | K42: =((K10*B10)+(K26*B26))/B42 -> #DIV/0! | N42: =(J42+J43)/(K42+K43) -> #DIV/0! | O42: =(J42+J43)/(G42+G43) -> #DIV/0! | P42: =G42*B42 -> #DIV/0! | R42: =Q42*B42 -> 0 | S42: =R42*[1]Cotizaciones!$B$5 -> 0 | T42: Colza / Soja 2da | AA42: =(J42+G42)*B42 -> #DIV/0!
B43: =B27+B11 -> 0 | C43: =((B11*C11)+(B27*C27))/B43 -> #DIV/0! | D43: =((D11*B11)+(D27*B27))/B43 -> #DIV/0! | E43: =E11 -> 450 | F43: =((F11*B11)+(F27*B27))/B43 -> #DIV/0! | G43: =((G11*B11)+(G27*B27))/B43 -> #DIV/0! | I43: =((I11*B11)+(I27*B27))/B43 -> #DIV/0! | J43: =((J11*B11)+(J27*B27))/B43 -> #DIV/0! | K43: =((K11*B11)+(K27*B27))/B43 -> #DIV/0! | P43: =G43*B43 -> #DIV/0! | Q43: ='[1]Soja 2da. C'!E60 -> #REF! | R43: =Q43*B43 -> #REF! | S43: =R43*[1]Cotizaciones!$B$5 -> #REF! | AA43: =(J43+G43)*B43 -> #DIV/0!
...

Sheet CASH FLOW
A1: PROYECCIÓN ALEA SIEMBRA: CASH FLOW SIEMBRAS PROPIAS
B3: 42856 | C3: 42887 | D3: 42917 | E3: 42948 | F3: 42979 | G3: 43009 | H3: 43040 | I3: 43070 | J3: 43101 | K3: 43132 | L3: 43160 | M3: 43191 | N3: 43221 | O3: 43252 | P3: TOTAL Con IVA
A4: TOTAL MENSUAL | B4: =+B36-B38+B90-B92+B118-B120+B132-B134 -> 0 | C4: =+C36-C38+C90-C92+C118-C120+C132-C134 -> 0 | D4: =+D36-D38+D90-D92+D118-D120+D132-D134 -> 0 | E4: =+E36-E38+E90-E92+E118-E120+E132-E134 -> 0 | F4: =+F36-F38+F90-F92+F118-F120+F132-F134 -> 0 | G4: =+G36-G38+G90-G92+G118-G120+G132-G134 -> 0 | H4: =+H36-H38+H90-H92+H118-H120+H132-H134 -> 0 | I4: =+I36-I38+I90-I92+I118-I120+I132-I134 -> 0 | J4: =+J36-J38+J90-J92+J118-J120+J132-J134+J50-J52 -> 0 | K4: =+K36-K38+K90-K92+K118-K120+K132-K134+K50-K52 -> 0 | L4: =+L36-L38+L90-L92+L118-L120+L132-L134+L50-L52 -> 0 | M4: =+M36-M38+M90-M92+M118-M120+M132-M134+M50-M52 -> 0 | N4: =+N36-N38+N90-N92+N118-N120+N132-N134+N50-N52 -> 0 | O4: =+O36-O38+O90-O92+O118-O120+O132-O134+O50-O52 -> 0 | P4: =SUM(B4:O4) -> 0 | Q4: c/iva
A5: TOTAL ACUMULADO | B5: =B4 -> 0 | C5: =B5+C4 -> 0 | D5: =C5+D4 -> 0 | E5: =D5+E4 -> 0 | F5: =E5+F4 -> 0 | G5: =F5+G4 -> 0 | H5: =G5+H4 -> 0 | I5: =H5+I4 -> 0 | J5: =I5+J4 -> 0 | ... O5: =N5+O4 -> 0
A7: TRIGO | B7: =B9-B11 -> 0 | C7: =C9-C11 -> 0 | D7: =D9-D11 -> -1950.165 | E7: =E9-E11 -> -1950.165 | F7: =F9-F11 -> -1950.165 | G7: =G9-G11 -> -1950.165 | H7: =H9-H11 -> -1950.165 | I7: =I9-I11 -> -1950.165 | ... O7: =O9-O11 -> 0 | P7: =SUM(B7:O7) -> -19501.65
B8: =B7 -> 0 | C8: =B8+C7 -> 0 | D8: =C8+D7 -> -1950.165 | E8: =D8+E7 -> -3900.33 | F8: =E8+F7 -> -5850.495 | G8: =F8+G7 -> -7800.66 | H8: =G8+H7 -> -9750.825 | I8: =H8+I7 -> -11700.99 | J8: =I8+J7 -> -13651.155 | ... O8: =N8+O7 -> -19501.65
A9: INGRESOS | B9: =B10 -> 0 | C9: =C10 -> 0 | D9: =D10 -> 0 | E9: =E10 -> 0 | F9: =F10 -> 0 | G9: =G10 -> 0 | H9: =H10 -> 0 | I9: =I10 -> 0 | ... O9: =O10 -> 0 | P9: =SUM(B9:O9) -> 0
A10: Ventas | J10: =('Trigo SP'!B79*'Trigo SP'!B3)*0.52 -> 0 | O10: =+('Trigo SP'!B79*'Trigo SP'!B3)*0.48 -> 0 | P10: =SUM(B10:O10) -> 0
A11: EGRESOS | B11: =SUM(B12:B19) -> 0 | C11: =SUM(C12:C19) -> 0 | D11: =SUM(D12:D19) -> 1950.165 | E11: =SUM(E12:E19) -> 1950.165 | F11: =SUM(F12:F19) -> 1950.165 | G11: =SUM(G12:G19) -> 1950.165 | H11: =SUM(H12:H19) -> 1950.165 | I11: =SUM(I12:I19) -> 1950.165 | ... O11: =SUM(O12:O19) -> 0 | P11: =SUM(B11:O11) -> 19501.65
A12: Arrendamiento | B12: =+'[2]Alquileres por campo'!$D$56+'[2]Alquileres por campo'!$E$56 -> 0 | C12: =+'[2]Alquileres por campo'!F56 -> 0 | D12: =+'[2]Alquileres por campo'!G56 -> 1950.165 | E12: =+'[2]Alquileres por campo'!H56 -> 1950.165 | F12: =+'[2]Alquileres por campo'!I56 -> 1950.165 | G12: =+'[2]Alquileres por campo'!J56 -> 1950.165 | H12: =+'[2]Alquileres por campo'!K56 -> 1950.165 | I12: =+'[2]Alquileres por campo'!L56 -> 1950.165 | J12: =+'[2]Alquileres por campo'!M56 -> 1950.165 | ... O12: =+'[2]Alquileres por campo'!R56 -> 0 | P12: =SUM(B12:O12) -> 19501.65
A13: Labores | B13: =((SUMIF('Trigo SP'!J8:J19,"MAYO",'Trigo SP'!E8:E19)*'Trigo SP'!B3)+(SUMIF('Trigo SS'!J8:J19,"MAYO",'Trigo SS'!E8:E19)*'Trigo SS'!B3))/9*'Tipo de Cambio Proyectado'!B2 -> 0 | C13: =((SUMIF('Trigo SP'!J8:J19,"JUNIO",'Trigo SP'!E8:E19)*'Trigo SP'!B3)+(SUMIF('Trigo SS'!J8:J19,"JUNIO",'Trigo SS'!E8:E19)*'Trigo SS'!B3))/9*'Tipo de Cambio Proyectado'!B3 -> 0 | D13: =(SUMIF('Trigo SP'!J8:J19,"JULIO",'Trigo SP'!E8:E19)*'Trigo SP'!B3)+(SUMIF('Trigo SS'!J8:J19,"JULIO",'Trigo SS'!E8:E19)*'Trigo SS'!B3)+(SUMIF('Trigo SS'!J8:J19,"JULIO/SEPTIEMBRE",'Trigo SS'!E8:E19)*'Trigo SS'!B3*0.5)+(SUMIF('Trigo SP'!J8:J19,"JULIO/SEPTIEMBRE",'Trigo SP'!E8:E19)*'Trigo SP'!B3*0.5) -> 0 | E13: =(SUMIF('Trigo SP'!J8:J19,"AGOSTO",'Trigo SP'!E8:E19)*'Trigo SP'!B3)+(SUMIF('Trigo SS'!J8:J19,"AGOSTO",'Trigo SS'!E8:E19)*'Trigo SS'!B3) -> 0 | F13: =(SUMIF('Trigo SP'!K8:K19,"SEPTIEMBRE",'Trigo SP'!F8:F19)*'Trigo SP'!B3)+(SUMIF('Trigo SS'!K8:K19,"SEPTIEMBRE",'Trigo SS'!F8:F19)*'Trigo SS'!B3)+(SUMIF('Trigo SS'!J8:J19,"JULIO/SEPTIEMBRE",'Trigo SS'!E8:E19)*'Trigo SS'!B3*0.5)+(SUMIF('Trigo SP'!J8:J19,"JULIO/SEPTIEMBRE",'Trigo SP'!E8:E19)*'Trigo SP'!B3*0.5) -> 0 | G13: =(SUMIF('Trigo SP'!K8:K19,"OCTUBRE",'Trigo SP'!F8:F19)*'Trigo SP'!B3)+(SUMIF('Trigo SS'!K8:K19,"OCTUBRE",'Trigo SS'!F8:F19)*'Trigo SS'!B3) -> 0 | H13: =(SUMIF('Trigo SP'!K8:K19,"NOVIEMBRE",'Trigo SP'!F8:F19)*'Trigo SP'!B3)+(SUMIF('Trigo SS'!K8:K19,"NOVIEMBRE",'Trigo SS'!F8:F19)*'Trigo SS'!B3) -> 0 | I13: =(SUMIF('Trigo SP'!J8:J18,"DICIEMBRE",'Trigo SP'!E8:E19)*'Trigo SP'!B3)+(SUMIF('Trigo SS'!K8:K19,"DICIEMBRE",'Trigo SS'!F8:F19)*'Trigo SS'!C3) -> 0 | J13: =(SUMIF('Trigo SP'!K8:K19,"ENERO",'Trigo SP'!F8:F19)*'Trigo SP'!C3)+(SUMIF('Trigo SS'!K8:K19,"ENERO",'Trigo SS'!F8:F19)*'Trigo SS'!C3) -> 0 | K13: =(SUMIF('Trigo SP'!K8:K19,"FEBRERO",'Trigo SP'!F8:F19)*'Trigo SP'!C3)+(SUMIF('Trigo SS'!K8:K19,"FEBRERO",'Trigo SS'!F8:F19)*'Trigo SS'!C3) -> 0 | L13: =(SUMIF('Trigo SP'!K8:K19,"MARZO",'Trigo SP'!F8:F19)*'Trigo SP'!C3)+(SUMIF('Trigo SS'!K8:K19,"MARZO",'Trigo SS'!F8:F19)*'Trigo SS'!C3) -> 0 | P13: =SUM(B13:O13) -> 0
A14: Insumos | B14: =(SUMIF('Trigo SP'!J38:J49,"MAYO",'Trigo SP'!E38:E49)*'Trigo SP'!B3)+(SUMIF('Trigo SS'!J37:J45,"MAYO",'Trigo SS'!E37:E45)*'Trigo SS'!B3) -> 0 | C14: =(SUMIF('Trigo SP'!J38:J49,"JUNIO",'Trigo SP'!E38:E49)*'Trigo SP'!B3)+(SUMIF('Trigo SS'!J37:J45,"JUNIO",'Trigo SS'!E37:E45)*'Trigo SS'!B3) -> 0 | D14: =(SUMIF('Trigo SP'!J38:J49,"JULIO",'Trigo SP'!E38:E49)*'Trigo SP'!B3)+(SUMIF('Trigo SS'!J37:J45,"JULIO",'Trigo SS'!E37:E45)*'Trigo SS'!B3) -> 0 | E14: =(SUMIF('Trigo SP'!J38:J49,"AGOSTO",'Trigo SP'!E38:E49)*'Trigo SP'!B3)+(SUMIF('Trigo SS'!J37:J45,"AGOSTO",'Trigo SS'!E37:E45)*'Trigo SS'!B3) -> 0 | F14: =(SUMIF('Trigo SP'!J38:J49,"SEPTIEMBRE",'Trigo SP'!E38:E49)*'Trigo SP'!B3)+(SUMIF('Trigo SS'!J37:J45,"SEPTIEMBRE",'Trigo SS'!E37:E45)*'Trigo SS'!B3) -> 0 | G14: =(SUMIF('Trigo SP'!J38:J49,"OCTUBRE",'Trigo SP'!E38:E49)*'Trigo SP'!B3)+(SUMIF('Trigo SS'!J37:J45,"OCTUBRE",'Trigo SS'!E37:E45)*'Trigo SS'!B3) -> 0 | H14: =(SUMIF('Trigo SP'!J38:J49,"NOVIEMBRE",'Trigo SP'!E38:E49)*'Trigo SP'!B3)+(SUMIF('Trigo SS'!J37:J45,"NOVIEMBRE",'Trigo SS'!E37:E45)*'Trigo SS'!B3) -> 0 | I14: =(SUMIF('Trigo SP'!J38:J49,"DICIEMBRE",'Trigo SP'!E38:E49)*'Trigo SP'!B3)+(SUMIF('Trigo SS'!J37:J45,"DICIEMBRE",'Trigo SS'!E37:E45)*'Trigo SS'!B3) -> 0 | J14: =(SUMIF('Trigo SP'!J38:J49,"ENERO",'Trigo SP'!E38:E49)*'Trigo SP'!B3)+(SUMIF('Trigo SS'!J37:J45,"ENERO",'Trigo SS'!E37:E45)*'Trigo SS'!B3) -> 0 | K14: =(SUMIF('Trigo SP'!J38:J49,"FEBRERO",'Trigo SP'!E38:E49)*'Trigo SP'!B3)+(SUMIF('Trigo SS'!J37:J45,"FEBRERO",'Trigo SS'!E37:E45)*'Trigo SS'!B3) -> 0 | L14: =(SUMIF('Trigo SP'!J38:J49,"MARZO",'Trigo SP'!E38:E49)*'Trigo SP'!B3)+(SUMIF('Trigo SS'!J37:J45,"MARZO",'Trigo SS'!E37:E45)*'Trigo SS'!B3) -> 0 | P14: =SUM(B14:O14) -> 0
A15: Fertilizante | B15: =('Trigo SP'!B3*SUMIF('Trigo SP'!J33:J34,"MAYO",'Trigo SP'!E33:E34))+('Trigo SS'!B3*SUMIF('Trigo SS'!J33:J34,"MAYO",'Trigo SS'!E33:E34)) -> 0 | C15: =('Trigo SP'!B3*SUMIF('Trigo SP'!J33:J34,"JUNIO",'Trigo SP'!E33:E34))+('Trigo SS'!B3*SUMIF('Trigo SS'!J33:J34,"JUNIO",'Trigo SS'!E33:E34)) -> 0 | D15: =('Trigo SP'!B3*SUMIF('Trigo SP'!J33:J34,"JULIO",'Trigo SP'!E33:E34))+('Trigo SS'!B3*SUMIF('Trigo SS'!J33:J34,"JULIO",'Trigo SS'!E33:E34)) -> 0 | I15: =+'Trigo SP'!I33 -> 0 | J15: =+'Trigo SP'!I34 -> 0 | P15: =SUM(B15:O15) -> 0
A16: Semilla | J16: ='Trigo SP'!B3*'Trigo SP'!E22+'Trigo SS'!B3*'Trigo SS'!E23 -> 0 | P16: =SUM(B16:O16) -> 0
A17: Cosecha// Comerc | J17: =('Trigo SP'!B3*('Trigo SP'!E53+'Trigo SP'!E70))+('Trigo SS'!B3*('Trigo SS'!D48+'Trigo SS'!E59)) -> 0 | P17: =SUM(B17:O17) -> 0
A18: Gerenciamiento | B18: =(('Trigo SP'!D29*'Trigo SP'!B3)+('Trigo SS'!D29*'Trigo SS'!B3))*0.1 -> 0 | C18: =(('Trigo SP'!D29*'Trigo SP'!B3)+('Trigo SS'!D29*'Trigo SS'!B3))*0.1 -> 0 | D18: =(('Trigo SP'!D29*'Trigo SP'!B3)+('Trigo SS'!D29*'Trigo SS'!B3))*0.1 -> 0 | E18: =(('Trigo SP'!D29*'Trigo SP'!B3)+('Trigo SS'!D29*'Trigo SS'!B3))*0.1 -> 0 | F18: =(('Trigo SP'!D29*'Trigo SP'!B3)+('Trigo SS'!D29*'Trigo SS'!B3))*0.1 -> 0 | G18: =(('Trigo SP'!D29*'Trigo SP'!B3)+('Trigo SS'!D29*'Trigo SS'!B3))*0.1 -> 0 | H18: =(('Trigo SP'!D29*'Trigo SP'!B3)+('Trigo SS'!D29*'Trigo SS'!B3))*0.1 -> 0 | I18: =(('Trigo SP'!D29*'Trigo SP'!B3)+('Trigo SS'!D29*'Trigo SS'!B3))*0.1 -> 0 | J18: =(('Trigo SP'!D29*'Trigo SP'!B3)+('Trigo SS'!D29*'Trigo SS'!B3))*0.1 -> 0 | K18: =(('Trigo SP'!D29*'Trigo SP'!B3)+('Trigo SS'!D29*'Trigo SS'!B3))*0.1 -> 0 | P18: =SUM(B18:O18) -> 0
A19: Seguro | K19: =('Trigo SP'!B3*'Trigo SP'!D54)+('Trigo SS'!D61*'Trigo SS'!B3) -> 0 | P19: =SUM(B19:O19) -> 0
A21: SOJA 2DA TRIGO | B21: =B23-B25 -> 0 | C21: =C23-C25 -> 0 | D21: =D23-D25 -> 0 | E21: =E23-E25 -> 0 | F21: =F23-F25 -> 0 | G21: =G23-G25 -> 0 | H21: =H23-H25 -> 0 | I21: =I23-I25 -> 0 | ... K21: =K23-K25 -> 0 | L21: 0 | M21: =M23-M25 -> 0 | N21: =N23-N25 -> 0 | O21: =O23-O25 -> 0 | P21: =SUM(B21:O21) -> 0
B22: =B21 -> 0 | C22: =B22+C21 -> 0 | D22: =C22+D21 -> 0 | E22: =D22+E21 -> 0 | F22: =E22+F21 -> 0 | G22: =F22+G21 -> 0 | H22: =G22+H21 -> 0 | I22: =H22+I21 -> 0 | J22: =I22+J21 -> 0 | K22: =J22+K21 -> 0 | L22: 0 | M22: 0 | N22: =M22+N21 -> 0 | O22: =N22+O21 -> 0
A23: INGRESOS | B23: =B24 -> 0 | C23: =C24 -> 0 | D23: =D24 -> 0 | E23: =E24 -> 0 | F23: =F24 -> 0 | G23: =G24 -> 0 | H23: =H24 -> 0 | I23: =I24 -> 0 | ... O23: =O24 -> 0 | P23: =SUM(B23:O23) -> 0
A24: Ventas | O24: ='Soja 2da. T'!B76*'Soja 2da. T'!B3 -> 0 | P24: =SUM(B24:O24) -> 0
A25: EGRESOS | B25: =SUM(B26:B32) -> 0 | C25: =SUM(C26:C32) -> 0 | D25: =SUM(D26:D32) -> 0 | E25: =SUM(E26:E32) -> 0 | F25: =SUM(F26:F32) -> 0 | G25: =SUM(G26:G32) -> 0 | H25: =SUM(H26:H32) -> 0 | I25: =SUM(I26:I32) -> 0 | ... O25: =SUM(O26:O32) -> 0 | P25: =SUM(B25:O25) -> 0
A26: Arrendamiento | P26: =SUM(B26:O26) -> 0
A27: Labores | D27: =(SUMIF('Soja 2da. T'!J7:J17,"JULIO",'Soja 2da. T'!E7:E17))*'Soja 2da. T'!B3 -> 0 | E27: =(SUMIF('Soja 2da. T'!J7:J17,"AGOSTO",'Soja 2da. T'!E7:E17))*'Soja 2da. T'!B3 -> 0 | F27: =(SUMIF('Soja 2da. T'!J7:J17,"SEPTIEMBRE",'Soja 2da. T'!E7:E17))*'Soja 2da. T'!B3 -> 0 | G27: =(SUMIF('Soja 2da. T'!J7:J17,"OCTUBREL",'Soja 2da. T'!E7:E17))*'Soja 2da. T'!B3 -> 0 | H27: =(SUMIF('Soja 2da. T'!J7:J17,"NOVIEMBRE",'Soja 2da. T'!E7:E17))*'Soja 2da. T'!B3 -> 0 | I27: =(SUMIF('Soja 2da. T'!J7:J17,"DICIEMBRE",'Soja 2da. T'!E7:E17))*'Soja 2da. T'!B3 -> 0 | J27: =(SUMIF('Soja 2da. T'!J7:J17,"ENERO",'Soja 2da. T'!E7:E17))*'Soja 2da. T'!B3 -> 0 | K27: =(SUMIF('Soja 2da. T'!J7:J17,"FEBRERO",'Soja 2da. T'!E7:E17))*'Soja 2da. T'!B3 -> 0 | L27: =(SUMIF('Soja 2da. T'!J7:J17,"MARZO",'Soja 2da. T'!E7:E17))*'Soja 2da. T'!B3 -> 0 | M27: =(SUMIF('Soja 2da. T'!J7:J17,"ABRIL",'Soja 2da. T'!E7:E17))*'Soja 2da. T'!B3 -> 0 | N27: =(SUMIF('Soja 2da. T'!J7:J17,"MAYO",'Soja 2da. T'!E7:E17))*'Soja 2da. T'!B3 -> 0 | O27: =(SUMIF('Soja 2da. T'!J7:J17,"JUNIO",'Soja 2da. T'!E7:E17))*'Soja 2da. T'!B3 -> 0 | P27: =SUM(B27:O27) -> 0
A28: Insumos | D28: =(SUMIF('Soja 2da. T'!J35:J44,"JULIO",'Soja 2da. T'!E35:E44)*'Soja 2da. T'!B3) -> 0 | E28: =(SUMIF('Soja 2da. T'!J35:J44,"AGOSTO",'Soja 2da. T'!E35:E44)*'Soja 2da. T'!B3) -> 0 | F28: =(SUMIF('Soja 2da. T'!J35:J44,"SEPTIEMBRE",'Soja 2da. T'!E35:E44)*'Soja 2da. T'!B3) -> 0 | G28: =(SUMIF('Soja 2da. T'!J35:J44,"OCTUBRE",'Soja 2da. T'!E35:E44)*'Soja 2da. T'!B3) -> 0 | H28: =(SUMIF('Soja 2da. T'!J35:J44,"NOVIEMBRE",'Soja 2da. T'!E35:E44)*'Soja 2da. T'!B3) -> 0 | I28: =(SUMIF('Soja 2da. T'!J35:J44,"DICIEMBRE",'Soja 2da. T'!E35:E44)*'Soja 2da. T'!B3) -> 0 | J28: =(SUMIF('Soja 2da. T'!J35:J44,"ENERO",'Soja 2da. T'!E35:E44)*'Soja 2da. T'!B3)+('Soja 2da. T'!B3*SUMIF('Soja 2da. T'!J35:J44,"ENERO/MARZO",'Soja 2da. T'!E35:E44)*0.5) -> 0 | K28: =(SUMIF('Soja 2da. T'!J35:J44,"FEBRERO",'Soja 2da. T'!E35:E44)*'Soja 2da. T'!B3) -> 0 | L28: =(SUMIF('Soja 2da. T'!J35:J44,"MARZO",'Soja 2da. T'!E35:E44)*'Soja 2da. T'!B3)+('Soja 2da. T'!B3*SUMIF('Soja 2da. T'!J35:J44,"ENERO/MARZO",'Soja 2da. T'!E35:E44)*0.5) -> 0 | M28: =(SUMIF('Soja 2da. T'!J35:J44,"ABRIL",'Soja 2da. T'!E35:E44)*'Soja 2da. T'!B3) -> 0 | N28: =(SUMIF('Soja 2da. T'!J35:J44,"MAYO",'Soja 2da. T'!E35:E44)*'Soja 2da. T'!B3) -> 0 | O28: =(SUMIF('Soja 2da. T'!J35:J44,"JUNIO",'Soja 2da. T'!E35:E44)*'Soja 2da. T'!B3) -> 0 | P28: =SUM(B28:O28) -> 0
A29: Semilla | J29: ='Soja 2da. T'!B3*'Soja 2da. T'!E21 -> 0 | P29: =SUM(B29:O29) -> 0
A30: Cosecha// Comerc | O30: ='Soja 2da. T'!B3*('Soja 2da. T'!E48+'Soja 2da. T'!E67) -> 0 | P30: =SUM(B30:O30) -> 0
A31: Gerenciamiento | F31: =('Soja 2da. T'!D27*'Soja 2da. T'!B3)*0.1 -> 0 | G31: =('Soja 2da. T'!D27*'Soja 2da. T'!B3)*0.1 -> 0 | H31: =('Soja 2da. T'!D27*'Soja 2da. T'!B3)*0.1 -> 0 | I31: =('Soja 2da. T'!D27*'Soja 2da. T'!B3)*0.1 -> 0 | J31: =('Soja 2da. T'!D27*'Soja 2da. T'!B3)*0.1 -> 0 | K31: =('Soja 2da. T'!D27*'Soja 2da. T'!B3)*0.1 -> 0 | L31: =('Soja 2da. T'!D27*'Soja 2da. T'!B3)*0.1 -> 0 | M31: =('Soja 2da. T'!D27*'Soja 2da. T'!B3)*0.1 -> 0 | N31: =('Soja 2da. T'!D27*'Soja 2da. T'!B3)*0.1 -> 0 | O31: =('Soja 2da. T'!D27*'Soja 2da. T'!B3)*0.1 -> 0 | P31: =SUM(B31:O31) -> 0
A32: Seguro | O32: ='Soja 2da. T'!E51*'Soja 2da. T'!B3 -> 0 | P32: =SUM(B32:O32) -> 0
A34: CEBADA | B34: =B36-B38 -> 0 | C34: =C36-C38 -> 0 | D34: =D36-D38 -> 0 | E34: =E36-E38 -> 0 | F34: =F36-F38 -> 0 | G34: =G36-G38 -> 0 | H34: =H36-H38 -> 0 | I34: =I36-I38 -> 0 | ... O34: =O36-O38 -> 0 | P34: =SUM(B34:O34) -> 0
B35: =B34 -> 0 | C35: =B35+C34 -> 0 | D35: =C35+D34 -> 0 | E35: =D35+E34 -> 0 | F35: =E35+F34 -> 0 | G35: =F35+G34 -> 0 | H35: =G35+H34 -> 0 | I35: =H35+I34 -> 0 | J35: =I35+J34 -> 0 | ... O35: =N35+O34 -> 0
A36: INGRESOS | B36: =B37 -> 0 | C36: =C37 -> 0 | D36: =D37 -> 0 | E36: =E37 -> 0 | F36: =F37 -> 0 | G36: =G37 -> 0 | H36: =H37 -> 0 | I36: =I37 -> 0 | ... O36: =O37 -> 0 | P36: =SUM(B36:O36) -> 0
A37: Ventas | J37: =+('Cebada SP'!B84*'Cebada SP'!B3)*0.165 -> 0 | K37: =+('Cebada SP'!B3*'Cebada SP'!B84)*0.172 -> 0 | L37: =+('Cebada SP'!B84*'Cebada SP'!B3)*0.663 -> 0 | P37: =SUM(B37:O37) -> 0
A38: EGRESOS | B38: =SUM(B39:B46) -> 0 | C38: =SUM(C39:C46) -> 0 | D38: =SUM(D39:D46) -> 0 | E38: =SUM(E39:E46) -> 0 | F38: =SUM(F39:F46) -> 0 | G38: =SUM(G39:G46) -> 0 | H38: =SUM(H39:H46) -> 0 | I38: =SUM(I39:I46) -> 0 | ... O38: =SUM(O39:O46) -> 0 | P38: =SUM(B38:O38) -> 0
A39: Arrendamiento | B39: =+'[2]Alquileres por campo'!$D$58+'[2]Alquileres por campo'!$E$58 -> 0 | C39: =+'[2]Alquileres por campo'!F58 -> 0 | D39: =+'[2]Alquileres por campo'!G58 -> 0 | E39: =+'[2]Alquileres por campo'!H58 -> 0 | F39: =+'[2]Alquileres por campo'!I58 -> 0 | G39: =+'[2]Alquileres por campo'!J58 -> 0 | H39: =+'[2]Alquileres por campo'!K58 -> 0 | I39: =+'[2]Alquileres por campo'!L58 -> 0 | J39: =+'[2]Alquileres por campo'!M58 -> 0 | ... O39: =+'[2]Alquileres por campo'!R58 -> 0 | P39: =SUM(B39:O39) -> 0
A40: Labores | B40: =((SUMIF('Cebada SP'!J8:J20,"MAYO",'Cebada SP'!E8:E20)*'Cebada SP'!B3)+(SUMIF('Cebada SS '!J8:J19,"MAYO",'Cebada SS '!E8:E19)*'Cebada SS '!B3))/9*'Tipo de Cambio Proyectado'!B2 -> 0 | C40: =(SUMIF('Cebada SP'!J8:J20,"JUNIO",'Cebada SP'!E8:E20)*'Cebada SP'!B3)+(SUMIF('Cebada SS '!J8:J19,"JUNIO",'Cebada SS '!E8:E19)*'Cebada SS '!B3) -> 0 | D40: =((SUMIF('Cebada SP'!J8:J20,"JULIO",'Cebada SP'!E8:E20)*'Cebada SP'!B3)+(SUMIF('Cebada SS '!J8:J19,"JULIO",'Cebada SS '!E8:E19)*'Cebada SS '!B3))/9*'Tipo de Cambio Proyectado'!B4 -> 0 | E40: =((SUMIF('Cebada SP'!J8:J20,"AGOSTO",'Cebada SP'!E8:E20)*'Cebada SP'!B3)+(SUMIF('Cebada SS '!J8:J19,"AGOSTO",'Cebada SS '!E8:E19)*'Cebada SS '!B3))/9*'Tipo de Cambio Proyectado'!B5 -> 0 | F40: =(SUMIF('Cebada SP'!J8:J20,"SEPTIEMBRE",'Cebada SP'!E8:E20)*'Cebada SP'!B3)+(SUMIF('Cebada SS '!J8:J19,"SEPTIEMBRE",'Cebada SS '!E8:E19)*'Cebada SS '!B3) -> 0 | G40: =(SUMIF('Cebada SP'!J8:J20,"OCTUBRE",'Cebada SP'!E8:E20)*'Cebada SP'!B3)+(SUMIF('Cebada SS '!J8:J19,"OCTUBRE",'Cebada SS '!E8:E19)*'Cebada SS '!B3) -> 0 | H40: =((SUMIF('Cebada SP'!J8:J20,"NOVIEMBRE",'Cebada SP'!E8:E20)*'Cebada SP'!B3)+(SUMIF('Cebada SS '!J8:J19,"NOVIEMBRE",'Cebada SS '!E8:E19)*'Cebada SS '!B3))/9*'Tipo de Cambio Proyectado'!B8 -> 0 | I40: =(SUMIF('Cebada SP'!J8:J20,"DICIEMBRE",'Cebada SP'!E8:E20)*'Cebada SP'!B3)+(SUMIF('Cebada SS '!J8:J19,"DICIEMBRE",'Cebada SS '!E8:E19)*'Cebada SS '!B3) -> 0 | J40: =(SUMIF('Cebada SP'!J8:J20,"ENERO",'Cebada SP'!E8:E20)*'Cebada SP'!B3)+(SUMIF('Cebada SS '!J8:J19,"ENERO",'Cebada SS '!E8:E19)*'Cebada SS '!B3) -> 0 | K40: =(SUMIF('Cebada SP'!J8:J20,"FEBRERO",'Cebada SP'!E8:E20)*'Cebada SP'!B3)+(SUMIF('Cebada SS '!J8:J19,"FEBRERO",'Cebada SS '!E8:E19)*'Cebada SS '!B3) -> 0 | L40: =(SUMIF('Cebada SP'!J8:J20,"MARZO",'Cebada SP'!E8:E20)*'Cebada SP'!B3)+(SUMIF('Cebada SS '!J8:J19,"MARZO",'Cebada SS '!E8:E19)*'Cebada SS '!B3) -> 0 | M40: =(SUMIF('Cebada SP'!J8:J20,"ABRIL",'Cebada SP'!E8:E20)*'Cebada SP'!B3)+(SUMIF('Cebada SS '!J8:J19,"ABRIL",'Cebada SS '!E8:E19)*'Cebada SS '!B3) -> 0 | P40: =SUM(B40:O40) -> 0
A41: Insumos | B41: =('Cebada SP'!B3*(SUMIF('Cebada SP'!J38:J50,"MAYO",'Cebada SP'!E38:E50)))+('Cebada SS '!B3*(SUMIF('Cebada SS '!J37:J48,"MAYO",'Cebada SS '!E37:E48))) -> 0 | C41: =('Cebada SP'!B3*(SUMIF('Cebada SP'!J38:J50,"JUNIO",'Cebada SP'!E38:E50)))+('Cebada SS '!B3*(SUMIF('Cebada SS '!J37:J48,"JUNIO",'Cebada SS '!E37:E48))) -> 0 | D41: =('Cebada SP'!B3*(SUMIF('Cebada SP'!J38:J50,"JULIO",'Cebada SP'!E38:E50)))+('Cebada SS '!B3*(SUMIF('Cebada SS '!J37:J48,"JULIO",'Cebada SS '!E37:E48))) -> 0 | E41: =('Cebada SP'!B3*(SUMIF('Cebada SP'!J38:J50,"AGOSTO",'Cebada SP'!E38:E50)))+('Cebada SS '!B3*(SUMIF('Cebada SS '!J37:J48,"AGOSTO",'Cebada SS '!E37:E48))) -> 0 | F41: =('Cebada SP'!B3*(SUMIF('Cebada SP'!J38:J50,"SEPTIEMBRE",'Cebada SP'!E38:E50)))+('Cebada SS '!B3*(SUMIF('Cebada SS '!J37:J48,"SEPTIEMBRE",'Cebada SS '!E37:E48))) -> 0 | G41: =('Cebada SP'!B3*(SUMIF('Cebada SP'!J38:J50,"OCTUBRE",'Cebada SP'!E38:E50)))+('Cebada SS '!B3*(SUMIF('Cebada SS '!J37:J48,"OCTUBRE",'Cebada SS '!E37:E48))) -> 0 | H41: =('Cebada SP'!B3*(SUMIF('Cebada SP'!J38:J50,"NOVIEMBRE",'Cebada SP'!E38:E50)))+('Cebada SS '!B3*(SUMIF('Cebada SS '!J37:J48,"NOVIEMBRE",'Cebada SS '!E37:E48))) -> 0 | I41: =('Cebada SP'!B3*(SUMIF('Cebada SP'!J38:J50,"DICIEMBRE",'Cebada SP'!E38:E50)))+('Cebada SS '!B3*(SUMIF('Cebada SS '!J37:J48,"DICIEMBRE",'Cebada SS '!E37:E48))) -> 0 | J41: =('Cebada SP'!B3*(SUMIF('Cebada SP'!J38:J50,"ENERO",'Cebada SP'!E38:E50)))+('Cebada SS '!B3*(SUMIF('Cebada SS '!J37:J48,"ENERO",'Cebada SS '!E37:E48))) -> 0 | K41: =('Cebada SP'!B3*(SUMIF('Cebada SP'!J38:J50,"FEBRERO",'Cebada SP'!E38:E50)))+('Cebada SS '!B3*(SUMIF('Cebada SS '!J37:J48,"FEBRERO",'Cebada SS '!E37:E48))) -> 0 | L41: =('Cebada SP'!B3*(SUMIF('Cebada SP'!J38:J50,"MARZO",'Cebada SP'!E38:E50)))+('Cebada SS '!B3*(SUMIF('Cebada SS '!J37:J48,"MARZO",'Cebada SS '!E37:E48))) -> 0 | P41: =SUM(B41:O41) -> 0
A42: Fertilizante | I42: =+'Cebada SP'!H33 -> 0 | J42: =+'Cebada SP'!H34 -> 0 | P42: =SUM(B42:O42) -> 0
A43: Semilla | J43: =('Cebada SP'!B3*'Cebada SP'!E23)+('Cebada SS '!E22*'Cebada SS '!B3) -> 0 | P43: =SUM(B43:O43) -> 0
A44: Cosecha// Comerc | J44: ='Cebada SP'!D53*'Cebada SP'!B3+'Cebada SP'!E73*'Cebada SP'!B3 -> 0 | P44: =SUM(B44:O44) -> 0
...

Sheet Cebada SP
A1: Proyección Cebada
A3: HECTAREAS | B3: 0
B5: CANTIDAD | C5: UNIDAD | D5: PRECIO | E5: TOTAL / HA | F5: % Costo | G5: Inv Real | H5: Mes | J5: MES CASH FLOW
D6: UNITARIO
A7: Labores
A8: Disco,rastra y rolo | B8: 0 | C8: Uni | D8: =+Cotizaciones!E8/Cotizaciones!M7 -> 29.014943 | E8: =B8*D8 -> 0 | H8: Abril | J8: MAYO
A9: Rolo picador | B9: 1 | C9: Uni | D9: 24 | E9: =B9*D9 -> 24 | H9: Abril | J9: MAYO
A10: Barbecho Quimico | B10: 2 | C10: Uni | D10: 6.5 | E10: =B10*D10 -> 13 | H10: 41030 | J10: MAYO
A11: Siembra | B11: 1 | C11: Uni | D11: 55 | E11: =B11*D11 -> 55 | H11: 41061 | J11: JULIO
A12: Pulverizacion Post-emergente | B12: 1 | C12: Uni | D12: 6.5 | E12: =B12*D12 -> 6.5 | F12: =42*105 -> 4410 | H12: 1/2 Julio | J12: AGOSTO
A13: Pulverización graminicidas | B13: 0 | C13: Uni | D13: 6.5 | E13: =B13*D13 -> 0 | H13: 1/2 Julio | J13: AGOSTO
A14: Aplicación Urea | B14: 1 | C14: Uni | D14: 11 | E14: =B14*D14 -> 11 | H14: 41091 | I14: 41122 | J14: JULIO
A15: Aplicación Urea | B15: 1 | C15: Uni | D15: 11 | E15: =B15*D15 -> 11 | J15: AGOSTO
A16: Aplicacion Fungicida Terrestre | B16: 2 | C16: Uni | D16: 6.5 | E16: =B16*D16 -> 13 | H16: 1/2 octubre | J16: NOVIEMBRE
A17: Muestreo de suelos | B17: 1 | C17: Uni | D17: 1 | E17: =B17*D17 -> 1 | H17: 41030 | J17: MAYO
A18: Analisis de suelos | B18: 0 | C18: Uni | D18: 1 | E18: =B18*D18 -> 0 | H18: 41030 | J18: MAYO
A19: Medicion satelital GPS | B19: 0 | C19: Uni | D19: 0 | E19: =B19*D19 -> 0 | J19: MAYO
A20: Limpieza, Curada e Inoculada | B20: 0 | C20: Uni | D20: 0 | E20: =B20*D20 -> 0 | J20: MAYO
C21: Total Labores | E21: =SUM(E8:E20) -> 134.5 | F21: =E21/E62 -> 0.12874386 | H21: =E21*$B$3 -> 0
A22: Semilla
A23: Semilla Cebada | B23: 140 | C23: Ton | D23: =+Cotizaciones!E40 -> 0.52 | E23: =B23*D23 -> 72.8 | H23: Canje | J23: ENERO
A24: Flete | D24: =+Cotizaciones!F26/1000 -> 0.035 | E24: =+D24*B23 -> 4.9 | H24: =E25*$B$3 -> 0
C25: Total Semilla | E25: =SUM(E23:E24) -> 77.7 | F25: =E25/E62 -> 0.074374707
A26: Arrendamiento | B26: 0.8 | C26: Uni | D26: =+'Resumen Proy'!C57 -> 426 | E26: =B26*D26 -> 340.8
C27: Total Arrendamiento | E27: =E26 -> 340.8 | F27: =E27/E62 -> 0.32621493 | H27: =+'[2]Alquileres por campo'!$S$58 -> 0
A29: Gerenciamiento | B29: 40 | C29: USD / Ha | D29: =+B29 -> 40 | E29: =D29 -> 40
C30: Total Gerenciamiento | E30: =E29 -> 40 | F30: =E30/E62 -> 0.038288137 | H30: =E30*$B$3 -> 0
A32: Fertilizantes
A33: Fosforados (en campo) | B33: 0.08 | C33: Ton. | D33: =+Cotizaciones!I25 -> 990 | E33: =B33*D33 -> 79.2 | H33: =+B3*E33 -> 0 | J33: DICIEMBRE
A34: Nitrogenados (en campo) | B34: 0.24 | C34: Ton. | D34: =+Cotizaciones!I34 -> 610 | E34: =B34*D34 -> 146.4 | H34: =+E34*B3 -> 0 | J34: ABRIL | K34: 200 tn se paga en marzo 100 tn en junio
A35: Flete | B35: =+B34+B33 -> 0.32 | C35: Ton. | D35: =+Cotizaciones!F26 -> 35 | E35: =+D35*B35 -> 11.2
C36: Total Fertilizantes | E36: =+E35+E34+E33 -> 236.8 | F36: =E36/E62 -> 0.22666577 | H36: =E36*$B$3 -> 0
A37: Agroquímicos
H38: siembra | J38: MAYO
A39: Paraquat | B39: 2 | C39: Lts. | D39: =+Cotizaciones!I45 -> 2.6 | E39: =B39*D39 -> 5.2 | H39: =A10 -> Barbecho Quimico | J39: MAYO
A40: yamato top | B40: 0.12 | C40: Lts. | D40: =+Cotizaciones!I50 -> 80 | E40: =B40*D40 -> 9.6 | H40: Fungicida | J40: MAYO
A41: Sulfosato | B41: 2 | C41: Lts. | D41: =+Cotizaciones!I28 -> 4.5 | E41: =B41*D41 -> 9 | H41: =A10 -> Barbecho Quimico | J41: MAYO
A42: 2,4-D | B42: 1.2 | C42: Lts. | D42: =+Cotizaciones!I5 -> 4.6 | E42: =B42*D42 -> 5.52 | H42: =A10 -> Barbecho Quimico | J42: MAYO
A43: MCPA | B43: 0.03 | C43: Lts. | D43: =+Cotizaciones!I32 -> 11 | E43: =B43*D43 -> 0.33 | H43: Barbecho Quimico | J43: MAYO
A44: Axial | B44: 0 | C44: Lts. | D44: =Cotizaciones!I11 -> 39 | E44: =B44*D44 -> 0 | H44: =+A13 -> Pulverización graminicidas | J44: ENERO
...

Sheet Cebada SS 
A1: Proyección Cebada Suelos Someros
A3: HECTAREAS | B3: ='Resumen Proy'!B24 -> 0
B5: CANTIDAD | C5: UNIDAD | D5: PRECIO | E5: TOTAL / HA | F5: % Costo | G5: Inv Real | H5: Mes | J5: MES CASH FLOW
D6: UNITARIO
A7: Labores
A8: Disco,rastra y rolo | B8: 0 | C8: Uni | D8: =Cotizaciones!F8 -> 0 | E8: =B8*D8 -> 0 | H8: Abril | J8: MAYO
A9: Rolo picador | B9: 0 | C9: Uni | D9: =Cotizaciones!F18 -> 17 | E9: =B9*D9 -> 0 | H9: Abril | J9: MAYO
A10: Barbecho Quimico | B10: 1 | C10: Uni | D10: =Cotizaciones!F17 -> 5 | E10: =B10*D10 -> 5 | H10: 41030 | J10: MAYO
A11: Siembra | B11: 1 | C11: Uni | D11: =Cotizaciones!F21 -> 42 | E11: =B11*D11 -> 42 | H11: 41061 | J11: JULIO
A12: Pulverizacion Post-emergente | B12: 1 | C12: Uni | D12: =Cotizaciones!F17 -> 5 | E12: =B12*D12 -> 5 | H12: 1/2 Julio | J12: AGOSTO
A13: Pulverización graminicidas | B13: 0.5 | C13: Uni | D13: =Cotizaciones!F17 -> 5 | E13: =B13*D13 -> 2.5 | H13: 1/2 Julio | J13: AGOSTO
A14: Aplicación Urea | B14: 1 | C14: Uni | D14: =Cotizaciones!F10 -> 0 | E14: =B14*D14 -> 0 | H14: 41091 | I14: 41122 | J14: JULIO
A15: Aplicación Fungicida | B15: 1 | C15: Uni | D15: =Cotizaciones!F17 -> 5 | E15: =B15*D15 -> 5 | H15: 1/2 octubre | J15: NOVIEMBRE
A16: Muestreo de suelos | B16: 0 | C16: Uni | D16: 1 | E16: =B16*D16 -> 0 | H16: 41030 | J16: MAYO
A17: Analisis de suelos | B17: 0 | C17: Uni | D17: 1 | E17: =B17*D17 -> 0 | H17: 41030 | J17: MAYO
A18: Medicion satelital GPS | B18: 0 | C18: Uni | D18: 1 | E18: =B18*D18 -> 0
A19: Limpieza, Curada e Inoculada | B19: 0 | C19: Uni | D19: =Cotizaciones!F12 -> 0 | E19: =B19*D19 -> 0
C20: Total Labores | E20: =SUM(E8:E19) -> 59.5 | F20: =E20/E70 -> 0.071476022 | H20: =E20*$B$3 -> 0
A21: Semilla
A22: Semilla Cebada Curada | B22: 0.12 | C22: Ton | D22: =Cotizaciones!E40 -> 0.52 | E22: =B22*D22 -> 0.0624 | H22: Canje | J22: ENERO
C23: Total Semilla | E23: =SUM(E22:E22) -> 0.0624 | F23: =E23/E70 -> 7.4959727e-05 | H23: =E23*$B$3 -> 0
A25: Arrendamiento | B25: 1 | C25: Uni | D25: =260*0.8 -> 208 | E25: =B25*D25 -> 208
C26: Total Arrendamiento | E26: =E25 -> 208 | F26: =E26/E70 -> 0.24986576 | H26: =E26*$B$3 -> 0
A28: Gerenciamiento | B28: 1 | C28: USD / Ha | D28: =B76*5% -> 61.25 | E28: =D28 -> 61.25
C29: Total Gerenciamiento | E29: =E28 -> 61.25 | F29: =E29/E70 -> 0.073578258 | H29: =E29*$B$3 -> 0
A31: Fertilizantes
A32: Fosforados (en campo) | B32: 0.07 | C32: Ton. | D32: =Cotizaciones!I25+Cotizaciones!F26 -> 1025 | E32: =B32*D32 -> 71.75 | J32: JUNIO
A33: Nitrogenados (en campo) | B33: 0.15 | C33: Ton. | D33: =Cotizaciones!I34+Cotizaciones!F26 -> 645 | E33: =B33*D33 -> 96.75 | J33: JUNIO
C35: Total Fertilizantes | E35: =SUM(E32:E33) -> 168.5 | F35: =E35/E70 -> 0.20241529 | H35: =E35*$B$3 -> 0
A36: Agroquímicos
A37: Curasemillas | B37: 0 | C37: Lts. | D37: =Cotizaciones!I22 -> 80 | E37: =B37*D37 -> 0 | H37: siembra | J37: MAYO
A38: Coadyugante (Lecitina) | B38: 0.3 | C38: Lts. | D38: =Cotizaciones!I21 -> 12 | E38: =B38*D38 -> 3.6 | H38: =A10 -> Barbecho Quimico | J38: MAYO | M38: =+A13 -> Pulverización graminicidas
A39: Aceite Vegetal | B39: 1 | C39: Lts. | D39: =Cotizaciones!I6 -> 3 | E39: =B39*D39 -> 3 | H39: Aplicación Fungicida | J39: MAYO
A40: Glifosato | B40: 3 | C40: Lts. | D40: =Cotizaciones!I28 -> 4.5 | E40: =B40*D40 -> 13.5 | H40: =A10 -> Barbecho Quimico | J40: MAYO
A41: 2,4-D | B41: 0.5 | C41: Lts. | D41: =Cotizaciones!I5 -> 4.6 | E41: =B41*D41 -> 2.3 | H41: =A10 -> Barbecho Quimico | J41: AGOSTO
A42: Axial | B42: 0.3 | C42: Lts. | D42: =Cotizaciones!I11 -> 39 | E42: =B42*D42 -> 11.7 | H42: =+A13 -> Pulverización graminicidas | J42: NOVIEMBRE
A43: Fungicida (orquesta) | B43: 1 | C43: Lts. | D43: =Cotizaciones!I26 -> 28 | E43: =B43*D43 -> 28 | H43: =A15 -> Aplicación Fungicida | J43: AGOSTO
A44: Soprano | B44: 0.6 | C44: Lts. | D44: =Cotizaciones!I46 -> 80 | E44: =B44*D44 -> 48
A45: Peack Pack | B45: 0.05 | C45: Dosis | D45: =Cotizaciones!I38 -> 125 | E45: =B45*D45 -> 6.25 | H45: =A12 -> Pulverizacion Post-emergente | J45: AGOSTO
A46: Dicamba | B46: 0.15 | C46: Lts. | D46: =Cotizaciones!I23 -> 7 | E46: =B46*D46 -> 1.05 | J46: NOVIEMBRE
...

Sheet Soja 2da. C
A1: Proyección Soja 2da Cebada
A3: HECTAREAS | B3: =+'Cebada SP'!B3 -> 0
D5: UNITARIO | J5: MES CASH FLOW
A6: Labores
A7: Disco,rastra y rolo | B7: 0 | C7: Uni | D7: =Cotizaciones!F8 -> 0 | E7: =B7*D7 -> 0
A8: Rolo picador | B8: 0 | C8: Uni | D8: =Cotizaciones!F18 -> 17 | E8: =B8*D8 -> 0
A9: Barbecho Quimico | B9: 0 | C9: Uni | D9: 6.5 | E9: =B9*D9 -> 0
A10: Siembra Directa | B10: 1 | C10: Uni | D10: 55 | E10: =B10*D10 -> 55 | H10: 41245 | J10: ENERO
A11: Pulverizacion Herbicida | B11: 1 | C11: Uni | D11: 6.5 | E11: =B11*D11 -> 6.5 | H11: 40909 | I11: 40940 | J11: ENERO
A12: Pulverizacion Herbicida | B12: 1 | C12: Uni | D12: 6.5 | E12: =B12*D12 -> 6.5 | J12: MARZO
A13: Aplicación terrestre Insecticida | B13: 1 | C13: Uni | D13: 6.5 | E13: =B13*D13 -> 6.5 | H13: 40941 | J13: MARZO
A14: Muestreo de suelos | B14: 0 | C14: Uni | D14: 0 | E14: =B14*D14 -> 0
A15: Analisis de suelos | B15: 0 | C15: Uni | D15: =Cotizaciones!F5 -> 0 | E15: =B15*D15 -> 0
A16: Medicion satelital GPS | B16: 0 | C16: Uni | D16: =Cotizaciones!F13 -> 0 | E16: =B16*D16 -> 0
A17: Limpieza, Curada e Inoculada | B17: 0 | C17: Uni | D17: 0 | E17: =(B20*D17)/1000 -> 0 | H17: 41244 | J17: ENERO
C18: Total Labores | E18: =SUM(E7:E17) -> 74.5 | F18: =E18/E57 -> 0.18671679 | G18: =E18*B3 -> 0
A19: Semilla
A20: Semilla de Soja | B20: 90 | C20: Kgs. | D20: =+Cotizaciones!E45/40 -> 0.875 | E20: =B20*D20 -> 78.75
A21: Flete | D21: =+'Cebada SP'!D35 -> 35 | E21: =+D21*B20/1000 -> 3.15 | H21: 41215 | J21: ENERO
C22: Total Semilla | E22: =SUM(E20:E21) -> 81.9 | F22: =E22/E57 -> 0.20526316 | G22: =E22*B3 -> 0
A24: Arrendamiento | B24: 0.2 | C24: Uni | D24: =+'Resumen Proy'!C57 -> 426 | E24: =B24*D24 -> 85.2
C25: Total Arrendamiento | E25: =E24 -> 85.2 | F25: =E25/E57 -> 0.21353383
A27: Gerenciamiento | B27: 10 | C27: USD / Ha | D27: =B27 -> 10 | E27: =D27 -> 10
C28: Total Gerenciamiento | E28: =E27 -> 10
A30: Fertilizantes
A31: Fosforados ( puesto en el campo ) | B31: 0 | C31: Ton. | D31: 0 | E31: =B31*D31 -> 0
A32: Arrancador Azufrado | B32: 0 | C32: Ton. | D32: 0 | E32: =B32*D32 -> 0
A33: Flete
C34: Total Fertilizantes | E34: =SUM(E31:E32) -> 0 | G34: =E34*B3 -> 0
A35: Agroquímicos
A36: Aceite | B36: 1 | C36: Lts. | D36: =Cotizaciones!I6 -> 3 | E36: =B36*D36 -> 3 | H36: =A13 -> Aplicación terrestre Insecticida | J36: ENERO/MARZO
A37: Fomesafen | B37: 0 | C37: Lts. | D37: =+Cotizaciones!I51 -> 7.2 | E37: =B37*D37 -> 0 | H37: =A11 -> Pulverizacion Herbicida | J37: ENERO/MARZO
A38: Sulfentrazone | B38: 0.3 | C38: Lts. | D38: =+Cotizaciones!I52 -> 19 | E38: =B38*D38 -> 5.7 | H38: =H37 -> Pulverizacion Herbicida | J38: ENERO/MARZO
A39: Inoculante | B39: =B20/3000 -> 0.03 | C39: Pack 3 Ton | D39: =Cotizaciones!I29 -> 250 | E39: =(D39*B39) -> 7.5 | H39: =A10 -> Siembra Directa | J39: ENERO
A40: Glifosato | B40: 4 | C40: Lts. | D40: =Cotizaciones!I28 -> 4.5 | E40: =B40*D40 -> 18 | H40: =H37 -> Pulverizacion Herbicida | J40: ENERO/MARZO
A41: 2,4-D | B41: 2 | C41: Lts. | D41: =Cotizaciones!I5 -> 4.6 | E41: =B41*D41 -> 9.2
A42: Clorimuron | B42: 0 | C42: Lts. | D42: =Cotizaciones!I18 -> 22.05 | E42: =B42*D42 -> 0
A43: Lambda | B43: 0.05 | C43: Lts. | D43: =Cotizaciones!I15 -> 20 | E43: =B43*D43 -> 1 | H43: =H36 -> Aplicación terrestre Insecticida | J43: MARZO
A44: Clorpirifos | B44: 0 | C44: Lts. | D44: =Cotizaciones!I19 -> 7 | E44: =B44*D44 -> 0 | H44: =H36 -> Aplicación terrestre Insecticida | J44: MARZO
A45: Coragen | B45: 0.05 | C45: Lts. | D45: =Cotizaciones!I30 -> 100 | E45: =B45*D45 -> 5 | J45: MARZO
...

Sheet Trigo SP
A1: Proyección Trigo Suelos Profundos
A3: HECTAREAS | B3: 0
B5: CANTIDAD | C5: UNIDAD | D5: PRECIO | E5: TOTAL / HA | G5: Total
D6: UNITARIO | J6: MES CASH FLOW
A7: Labores
A8: Disco,rastra y rolo | B8: 0 | C8: Uni | D8: =+'Cebada SP'!D8 -> 29.014943 | E8: =B8*D8 -> 0 | J8: MAYO
A9: Rolo picador | B9: 1 | C9: Uni | D9: 23 | E9: =B9*D9 -> 23 | J9: MAYO
A10: Barbecho Quimico | B10: 2 | C10: Uni | D10: 6.5 | E10: =B10*D10 -> 13 | G10: 41030 | J10: MAYO
A11: Siembra | B11: 1 | C11: Uni | D11: 55 | E11: =B11*D11 -> 55 | G11: 2 mayo, 1 jun | J11: JUNIO
A12: Pulverizacion Post-emergente | B12: 1 | C12: Uni | D12: 6.5 | E12: =B12*D12 -> 6.5 | G12: 41091 | J12: AGOSTO
A13: Pulverización graminicidas | B13: 0 | C13: Uni | D13: 6.5 | E13: =B13*D13 -> 0 | G13: 41091 | J13: AGOSTO
A14: Aplicación Urea | B14: 2 | C14: Uni | D14: 11 | E14: =B14*D14 -> 22 | G14: 41061 | H14: 41122 | J14: JULIO/SEPTIEMBRE
A15: Aplicación terrestre Fungicida/Insecticida | B15: 2 | C15: Uni | D15: 6.5 | E15: =B15*D15 -> 13 | G15: 41184 | J15: DICIEMBRE
A16: Muestreo de suelos | B16: 1 | C16: Uni | D16: 0 | E16: =B16*D16 -> 0 | G16: =+G10 -> 41030 | J16: MAYO
A17: Analisis de suelos | B17: 1 | C17: Uni | D17: 1 | E17: =B17*D17 -> 1 | G17: =+G10 -> 41030 | J17: MAYO
A18: Medicion satelital GPS | B18: 0 | C18: Uni | D18: 0 | E18: =B18*D18 -> 0
A19: Limpieza, Curada e Inoculada | B19: 0 | C19: Uni | D19: =+'Cebada SP'!D20 -> 0 | E19: =B19*D19 -> 0 | J19: MAYO
C20: Total Labores | E20: =SUM(E8:E19) -> 133.5 | F20: =E20/E60 -> 0.13001938 | G20: =E20*D1 -> 0 | I20: =+E20*B3 -> 0
A21: Semilla
A22: Semilla de trigo curada | B22: 140 | C22: Kgs. | D22: =Cotizaciones!E47 -> 0.525 | E22: =B22*D22 -> 73.5 | G22: =+A11 -> Siembra
A23: Flete | D23: =+D35 -> 35 | E23: =+D23*B22/1000 -> 4.9 | J23: JULIO
C24: Total Semilla | E24: =SUM(E22:E23) -> 78.4 | F24: =E24/E60 -> 0.076355951 | G24: =E24*D1 -> 0 | H24: =+E24*B3 -> 0 | I24: =+E24*B3 -> 0
A26: Arrendamiento | B26: 0.8 | C26: Uni | D26: =+'Resumen Proy'!C57 -> 426 | E26: =B26*D26 -> 340.8
C27: Total Arrendamiento | E27: =E26 -> 340.8 | F27: =E27/E60 -> 0.33191464 | G27: =E27*D1 -> 0 | I27: =+'[2]Alquileres por campo'!$S$56 -> 19501.65
A29: Gerenciamiento | B29: 30 | C29: USD / Ha | D29: =B29 -> 30 | E29: =D29 -> 30
C30: Total Gerenciamiento | E30: =E29 -> 30 | F30: =E30/E60 -> 0.029217838 | G30: =E30*D1 -> 0
A32: Fertilizantes
A33: Fosforados | B33: 0.08 | C33: Ton. | D33: =+Cotizaciones!I25 -> 990 | E33: =B33*D33 -> 79.2 | G33: =+G22 -> Siembra | I33: =+E33*B3 -> 0 | J33: DICIEMBRE
A34: Nitrogenados | B34: 0.22 | C34: Ton. | D34: =Cotizaciones!I34 -> 610 | E34: =B34*D34 -> 134.2 | G34: =+G14 -> 41061 | H34: =+H14 -> 41122 | I34: =+E34*B3 -> 0 | J34: ENERO
A35: Flete | B35: =+B34+B33 -> 0.3 | D35: =+'Cebada SP'!D35 -> 35 | E35: =+D35*B35 -> 10.5
C36: Total Fertilizantes | E36: =+E35+E34+E33 -> 223.9 | F36: =E36/E60 -> 0.21806247 | G36: =E36*D1 -> 0 | H36: =+E36*B3 -> 0
A37: Agroquímicos
A38: Paraquat | B38: 2 | C38: Lts. | D38: =+Cotizaciones!I45 -> 2.6 | E38: =B38*D38 -> 5.2 | G38: =+G33 -> Siembra | J38: MAYO
A39: Piroxasulfone | B39: 0.12 | C39: Lts. | D39: =+Cotizaciones!I50 -> 80 | E39: =B39*D39 -> 9.6 | G39: =+A10 -> Barbecho Quimico | I39: =+A12 -> Pulverizacion Post-emergente | J39: MAYO
A40: Sulfosato | B40: 2 | C40: Lts. | D40: =+Cotizaciones!I43 -> 4.5 | E40: =B40*D40 -> 9 | G40: =+A10 -> Barbecho Quimico | J40: NOVIEMBRE
A41: 2,4-D | B41: 1.2 | C41: Lts. | D41: =Cotizaciones!I5 -> 4.6 | E41: =B41*D41 -> 5.52 | G41: =+G40 -> Barbecho Quimico | J41: NOVIEMBRE
A42: Picloran | B42: 0 | C42: Lts. | D42: =Cotizaciones!I36 -> 7 | E42: =B42*D42 -> 0 | J42: NOVIEMBRE
A43: batalium | B43: 0.5 | C43: Lts. | D43: 47 | E43: =B43*D43 -> 23.5 | G43: =+A13 -> Pulverización graminicidas | J43: ENERO
A44: Fungicida (Opera) | B44: 1.3 | C44: Lts. | D44: =Cotizaciones!I26 -> 28 | E44: =D44*B44 -> 36.4 | G44: =+A15 -> Aplicación terrestre Fungicida/Insecticida | J44: NOVIEMBRE
A45: Metsulfurón | B45: 0.05 | C45: Kg. | D45: =Cotizaciones!I37 -> 35 | E45: =B45*D45 -> 1.75 | G45: =+G39 -> Barbecho Quimico | J45: MAYO
...

Sheet Camelina
A1: Proyección Soja Suelos Profundos
A3: HECTAREAS | B3: 0
B5: CANTIDAD | C5: UNIDAD | D5: PRECIO | E5: TOTAL / HA | F5: % Costo | G5: Inv Real | H5: Mes
D6: UNITARIO | J6: MES CASH FLOW
A7: Labores
A8: Disco,rastra y rolo | B8: 0 | C8: Uni | D8: =Cotizaciones!F8 -> 0 | E8: =B8*D8 -> 0
A9: Rolo picador | B9: 0 | C9: Uni | D9: 24 | E9: =B9*D9 -> 0 | J9: JUNIO
A10: Barbecho Quimico | B10: 2 | C10: Uni | D10: 7 | E10: =B10*D10 -> 14 | H10: 41061 | I10: 41153 | J10: AGOSTO
A11: Preemergente | B11: 1 | C11: UNI | D11: 8 | E11: =B11*D11 -> 8 | J11: OCTUBRE
A12: Siembra Directa | B12: 1 | C12: Uni | D12: 55 | E12: =B12*D12 -> 55 | H12: 41214 | J12: DICIEMBRE
A13: Fertilizacion | B13: 1 | C13: Uni | D13: 12 | E13: =B13*D13 -> 12 | H13: 41215 | I13: 40940 | J13: DICIEMBRE
A14: Pulverizacion | B14: 0 | C14: Uni | D14: 7 | E14: =B14*D14 -> 0 | J14: FEBRERO
A15: Aplicación terrestre Insecticida/ Fungicida | B15: 0 | C15: Uni | D15: =+D14 -> 7 | E15: =B15*D15 -> 0 | H15: 40941 | J15: MARZO
A16: Monitoreo B y BB. | B16: 0 | C16: Uni | D16: 6 | E16: =B16*D16 -> 0 | H16: 41183 | J16: NOVIEMBRE
A17: Limpieza e inoculado | B17: 0 | C17: Uni | D17: =+((Cotizaciones!E12/Cotizaciones!M14)/1000)*B23 -> 0.50819816 | E17: =B17*D17 -> 0
A18: Aplicacion Cebo | B18: 0 | C18: Uni | D18: =Cotizaciones!F6 -> 5 | E18: =B18*D18 -> 0 | H18: 41214 | J18: NOVIEMBRE
C20: Total Labores | E20: =SUM(E8:E19) -> 89 | F20: =E20/E64 -> 0.22277847 | G20: =E20*D1 -> 0
A21: Semilla
A23: Semilla de Soja propia | B23: 24 | C23: Kgs. | D23: 0.45 | E23: =B23*D23 -> 10.8 | H23: 41214 | J23: NOVIEMBRE
C24: Total Semilla | E24: =SUM(E23:E23) -> 10.8 | F24: =E24/E64 -> 0.027033792 | G24: =E24*D1 -> 0
A26: Arrendamiento | B26: 0 | C26: Uni | D26: ='Resumen Proy'!D15 -> 426 | E26: =B26*D26 -> 0
C27: Total Arrendamiento | E27: =E26 -> 0 | F27: =E27/E64 -> 0 | G27: =E27*D1 -> 0
A29: Gerenciamiento | B29: =0.3*40 -> 12 | C29: USD / Ha | D29: =B29 -> 12 | E29: =D29 -> 12
C30: Total Gerenciamiento | E30: =E29 -> 12 | F30: =E30/E64 -> 0.030037547 | G30: =E30*D1 -> 0
A32: Fertilizantes
A33: Fosforados | B33: 0.07 | C33: Ton. | D33: =Cotizaciones!I25 -> 990 | E33: =B33*D33 -> 69.3 | H33: 41214
A34: UREA | B34: 0.06 | C34: Ton. | D34: =+Cotizaciones!I34 -> 610 | E34: =B34*D34 -> 36.6 | I34: =+E34*B3 -> 0 | J34: NOVIEMBRE
B35: =+B34+B33 -> 0.13 | D35: =+'Cebada SP'!D35 -> 35 | E35: =+D35*B35 -> 4.55
C36: Total Fertilizantes | E36: =+E35+E34+E33 -> 110.45 | F36: =E36/E64 -> 0.27647059 | G36: =E36*D1 -> 0
A37: Agroquímicos
